---------------------------------------------------------------
[ 2017-08-27T12:32:47+08:00 ] 127.0.0.1 127.0.0.1 GET /index.php/api/v1/selProduct
[ error ] [1]Uncaught exception 'think\exception\ErrorException' with message 'Argument 1 passed to app\lib\exception\ExceptionHandler::render() must be an instance of think\Exception, instance of think\exception\RouteNotFoundException given, called in C:\Users\cheyod\Desktop\Home\WWW\bigbase\thinkphp\library\think\Error.php on line 47 and defined' in C:\Users\cheyod\Desktop\Home\WWW\bigbase\application\lib\exception\ExceptionHandler.php:15
Stack trace:
#0 C:\Users\cheyod\Desktop\Home\WWW\bigbase\application\lib\exception\ExceptionHandler.php(15): think\Error::appError(4096, 'Argument 1 pass...', 'C:\\Users\\cheyod...', 15, Array)
#1 C:\Users\cheyod\Desktop\Home\WWW\bigbase\thinkphp\library\think\Error.php(47): app\lib\exception\ExceptionHandler->render(Object(think\exception\RouteNotFoundException))
#2 [internal function]: think\Error::appException(Object(think\exception\RouteNotFoundException))
#3 {main}
  thrown
[ error ] Uncaught exception 'think\exception\ErrorException' with message 'Argument 1 passed to app\lib\exception\ExceptionHandler::render() must be an instance of think\Exception, instance of think\exception\RouteNotFoundException given, called in C:\Users\cheyod\Desktop\Home\WWW\bigbase\thinkphp\library\think\Error.php on line 47 and defined' in C:\Users\cheyod\Desktop\Home\WWW\bigbase\application\lib\exception\ExceptionHandler.php:15
Stack trace:
#0 C:\Users\cheyod\Desktop\Home\WWW\bigbase\application\lib\exception\ExceptionHandler.php(15): think\Error::appError(4096, 'Argument 1 pass...', 'C:\\Users\\cheyod...', 15, Array)
#1 C:\Users\cheyod\Desktop\Home\WWW\bigbase\thinkphp\library\think\Error.php(47): app\lib\exception\ExceptionHandler->render(Object(think\exception\RouteNotFoundException))
#2 [internal function]: think\Error::appException(Object(think\exception\RouteNotFoundException))
#3 {main}
  thrown
---------------------------------------------------------------
[ 2017-08-27T12:33:25+08:00 ] 127.0.0.1 127.0.0.1 GET /index.php/api/v1/selProduct
[ error ] [1]Uncaught exception 'think\exception\ErrorException' with message 'Argument 1 passed to app\lib\exception\ExceptionHandler::render() must be an instance of think\Exception, instance of think\exception\RouteNotFoundException given, called in C:\Users\cheyod\Desktop\Home\WWW\bigbase\thinkphp\library\think\Error.php on line 47 and defined' in C:\Users\cheyod\Desktop\Home\WWW\bigbase\application\lib\exception\ExceptionHandler.php:15
Stack trace:
#0 C:\Users\cheyod\Desktop\Home\WWW\bigbase\application\lib\exception\ExceptionHandler.php(15): think\Error::appError(4096, 'Argument 1 pass...', 'C:\\Users\\cheyod...', 15, Array)
#1 C:\Users\cheyod\Desktop\Home\WWW\bigbase\thinkphp\library\think\Error.php(47): app\lib\exception\ExceptionHandler->render(Object(think\exception\RouteNotFoundException))
#2 [internal function]: think\Error::appException(Object(think\exception\RouteNotFoundException))
#3 {main}
  thrown
[ error ] Uncaught exception 'think\exception\ErrorException' with message 'Argument 1 passed to app\lib\exception\ExceptionHandler::render() must be an instance of think\Exception, instance of think\exception\RouteNotFoundException given, called in C:\Users\cheyod\Desktop\Home\WWW\bigbase\thinkphp\library\think\Error.php on line 47 and defined' in C:\Users\cheyod\Desktop\Home\WWW\bigbase\application\lib\exception\ExceptionHandler.php:15
Stack trace:
#0 C:\Users\cheyod\Desktop\Home\WWW\bigbase\application\lib\exception\ExceptionHandler.php(15): think\Error::appError(4096, 'Argument 1 pass...', 'C:\\Users\\cheyod...', 15, Array)
#1 C:\Users\cheyod\Desktop\Home\WWW\bigbase\thinkphp\library\think\Error.php(47): app\lib\exception\ExceptionHandler->render(Object(think\exception\RouteNotFoundException))
#2 [internal function]: think\Error::appException(Object(think\exception\RouteNotFoundException))
#3 {main}
  thrown
---------------------------------------------------------------
[ 2017-08-27T12:33:25+08:00 ] 127.0.0.1 127.0.0.1 GET /index.php/api/v1/selProduct
[ error ] [1]Uncaught exception 'think\exception\ErrorException' with message 'Argument 1 passed to app\lib\exception\ExceptionHandler::render() must be an instance of think\Exception, instance of think\exception\RouteNotFoundException given, called in C:\Users\cheyod\Desktop\Home\WWW\bigbase\thinkphp\library\think\Error.php on line 47 and defined' in C:\Users\cheyod\Desktop\Home\WWW\bigbase\application\lib\exception\ExceptionHandler.php:15
Stack trace:
#0 C:\Users\cheyod\Desktop\Home\WWW\bigbase\application\lib\exception\ExceptionHandler.php(15): think\Error::appError(4096, 'Argument 1 pass...', 'C:\\Users\\cheyod...', 15, Array)
#1 C:\Users\cheyod\Desktop\Home\WWW\bigbase\thinkphp\library\think\Error.php(47): app\lib\exception\ExceptionHandler->render(Object(think\exception\RouteNotFoundException))
#2 [internal function]: think\Error::appException(Object(think\exception\RouteNotFoundException))
#3 {main}
  thrown
[ error ] Uncaught exception 'think\exception\ErrorException' with message 'Argument 1 passed to app\lib\exception\ExceptionHandler::render() must be an instance of think\Exception, instance of think\exception\RouteNotFoundException given, called in C:\Users\cheyod\Desktop\Home\WWW\bigbase\thinkphp\library\think\Error.php on line 47 and defined' in C:\Users\cheyod\Desktop\Home\WWW\bigbase\application\lib\exception\ExceptionHandler.php:15
Stack trace:
#0 C:\Users\cheyod\Desktop\Home\WWW\bigbase\application\lib\exception\ExceptionHandler.php(15): think\Error::appError(4096, 'Argument 1 pass...', 'C:\\Users\\cheyod...', 15, Array)
#1 C:\Users\cheyod\Desktop\Home\WWW\bigbase\thinkphp\library\think\Error.php(47): app\lib\exception\ExceptionHandler->render(Object(think\exception\RouteNotFoundException))
#2 [internal function]: think\Error::appException(Object(think\exception\RouteNotFoundException))
#3 {main}
  thrown
---------------------------------------------------------------
[ 2017-08-27T12:33:25+08:00 ] 127.0.0.1 127.0.0.1 GET /index.php/api/v1/selProduct
[ error ] [1]Uncaught exception 'think\exception\ErrorException' with message 'Argument 1 passed to app\lib\exception\ExceptionHandler::render() must be an instance of think\Exception, instance of think\exception\RouteNotFoundException given, called in C:\Users\cheyod\Desktop\Home\WWW\bigbase\thinkphp\library\think\Error.php on line 47 and defined' in C:\Users\cheyod\Desktop\Home\WWW\bigbase\application\lib\exception\ExceptionHandler.php:15
Stack trace:
#0 C:\Users\cheyod\Desktop\Home\WWW\bigbase\application\lib\exception\ExceptionHandler.php(15): think\Error::appError(4096, 'Argument 1 pass...', 'C:\\Users\\cheyod...', 15, Array)
#1 C:\Users\cheyod\Desktop\Home\WWW\bigbase\thinkphp\library\think\Error.php(47): app\lib\exception\ExceptionHandler->render(Object(think\exception\RouteNotFoundException))
#2 [internal function]: think\Error::appException(Object(think\exception\RouteNotFoundException))
#3 {main}
  thrown
[ error ] Uncaught exception 'think\exception\ErrorException' with message 'Argument 1 passed to app\lib\exception\ExceptionHandler::render() must be an instance of think\Exception, instance of think\exception\RouteNotFoundException given, called in C:\Users\cheyod\Desktop\Home\WWW\bigbase\thinkphp\library\think\Error.php on line 47 and defined' in C:\Users\cheyod\Desktop\Home\WWW\bigbase\application\lib\exception\ExceptionHandler.php:15
Stack trace:
#0 C:\Users\cheyod\Desktop\Home\WWW\bigbase\application\lib\exception\ExceptionHandler.php(15): think\Error::appError(4096, 'Argument 1 pass...', 'C:\\Users\\cheyod...', 15, Array)
#1 C:\Users\cheyod\Desktop\Home\WWW\bigbase\thinkphp\library\think\Error.php(47): app\lib\exception\ExceptionHandler->render(Object(think\exception\RouteNotFoundException))
#2 [internal function]: think\Error::appException(Object(think\exception\RouteNotFoundException))
#3 {main}
  thrown
---------------------------------------------------------------
[ 2017-08-27T12:33:25+08:00 ] 127.0.0.1 127.0.0.1 GET /index.php/api/v1/selProduct
[ error ] [1]Uncaught exception 'think\exception\ErrorException' with message 'Argument 1 passed to app\lib\exception\ExceptionHandler::render() must be an instance of think\Exception, instance of think\exception\RouteNotFoundException given, called in C:\Users\cheyod\Desktop\Home\WWW\bigbase\thinkphp\library\think\Error.php on line 47 and defined' in C:\Users\cheyod\Desktop\Home\WWW\bigbase\application\lib\exception\ExceptionHandler.php:15
Stack trace:
#0 C:\Users\cheyod\Desktop\Home\WWW\bigbase\application\lib\exception\ExceptionHandler.php(15): think\Error::appError(4096, 'Argument 1 pass...', 'C:\\Users\\cheyod...', 15, Array)
#1 C:\Users\cheyod\Desktop\Home\WWW\bigbase\thinkphp\library\think\Error.php(47): app\lib\exception\ExceptionHandler->render(Object(think\exception\RouteNotFoundException))
#2 [internal function]: think\Error::appException(Object(think\exception\RouteNotFoundException))
#3 {main}
  thrown
[ error ] Uncaught exception 'think\exception\ErrorException' with message 'Argument 1 passed to app\lib\exception\ExceptionHandler::render() must be an instance of think\Exception, instance of think\exception\RouteNotFoundException given, called in C:\Users\cheyod\Desktop\Home\WWW\bigbase\thinkphp\library\think\Error.php on line 47 and defined' in C:\Users\cheyod\Desktop\Home\WWW\bigbase\application\lib\exception\ExceptionHandler.php:15
Stack trace:
#0 C:\Users\cheyod\Desktop\Home\WWW\bigbase\application\lib\exception\ExceptionHandler.php(15): think\Error::appError(4096, 'Argument 1 pass...', 'C:\\Users\\cheyod...', 15, Array)
#1 C:\Users\cheyod\Desktop\Home\WWW\bigbase\thinkphp\library\think\Error.php(47): app\lib\exception\ExceptionHandler->render(Object(think\exception\RouteNotFoundException))
#2 [internal function]: think\Error::appException(Object(think\exception\RouteNotFoundException))
#3 {main}
  thrown
---------------------------------------------------------------
[ 2017-08-27T12:33:26+08:00 ] 127.0.0.1 127.0.0.1 GET /index.php/api/v1/selProduct
[ error ] [1]Uncaught exception 'think\exception\ErrorException' with message 'Argument 1 passed to app\lib\exception\ExceptionHandler::render() must be an instance of think\Exception, instance of think\exception\RouteNotFoundException given, called in C:\Users\cheyod\Desktop\Home\WWW\bigbase\thinkphp\library\think\Error.php on line 47 and defined' in C:\Users\cheyod\Desktop\Home\WWW\bigbase\application\lib\exception\ExceptionHandler.php:15
Stack trace:
#0 C:\Users\cheyod\Desktop\Home\WWW\bigbase\application\lib\exception\ExceptionHandler.php(15): think\Error::appError(4096, 'Argument 1 pass...', 'C:\\Users\\cheyod...', 15, Array)
#1 C:\Users\cheyod\Desktop\Home\WWW\bigbase\thinkphp\library\think\Error.php(47): app\lib\exception\ExceptionHandler->render(Object(think\exception\RouteNotFoundException))
#2 [internal function]: think\Error::appException(Object(think\exception\RouteNotFoundException))
#3 {main}
  thrown
[ error ] Uncaught exception 'think\exception\ErrorException' with message 'Argument 1 passed to app\lib\exception\ExceptionHandler::render() must be an instance of think\Exception, instance of think\exception\RouteNotFoundException given, called in C:\Users\cheyod\Desktop\Home\WWW\bigbase\thinkphp\library\think\Error.php on line 47 and defined' in C:\Users\cheyod\Desktop\Home\WWW\bigbase\application\lib\exception\ExceptionHandler.php:15
Stack trace:
#0 C:\Users\cheyod\Desktop\Home\WWW\bigbase\application\lib\exception\ExceptionHandler.php(15): think\Error::appError(4096, 'Argument 1 pass...', 'C:\\Users\\cheyod...', 15, Array)
#1 C:\Users\cheyod\Desktop\Home\WWW\bigbase\thinkphp\library\think\Error.php(47): app\lib\exception\ExceptionHandler->render(Object(think\exception\RouteNotFoundException))
#2 [internal function]: think\Error::appException(Object(think\exception\RouteNotFoundException))
#3 {main}
  thrown
---------------------------------------------------------------
[ 2017-08-27T12:33:26+08:00 ] 127.0.0.1 127.0.0.1 GET /index.php/api/v1/selProduct
[ error ] [1]Uncaught exception 'think\exception\ErrorException' with message 'Argument 1 passed to app\lib\exception\ExceptionHandler::render() must be an instance of think\Exception, instance of think\exception\RouteNotFoundException given, called in C:\Users\cheyod\Desktop\Home\WWW\bigbase\thinkphp\library\think\Error.php on line 47 and defined' in C:\Users\cheyod\Desktop\Home\WWW\bigbase\application\lib\exception\ExceptionHandler.php:15
Stack trace:
#0 C:\Users\cheyod\Desktop\Home\WWW\bigbase\application\lib\exception\ExceptionHandler.php(15): think\Error::appError(4096, 'Argument 1 pass...', 'C:\\Users\\cheyod...', 15, Array)
#1 C:\Users\cheyod\Desktop\Home\WWW\bigbase\thinkphp\library\think\Error.php(47): app\lib\exception\ExceptionHandler->render(Object(think\exception\RouteNotFoundException))
#2 [internal function]: think\Error::appException(Object(think\exception\RouteNotFoundException))
#3 {main}
  thrown
[ error ] Uncaught exception 'think\exception\ErrorException' with message 'Argument 1 passed to app\lib\exception\ExceptionHandler::render() must be an instance of think\Exception, instance of think\exception\RouteNotFoundException given, called in C:\Users\cheyod\Desktop\Home\WWW\bigbase\thinkphp\library\think\Error.php on line 47 and defined' in C:\Users\cheyod\Desktop\Home\WWW\bigbase\application\lib\exception\ExceptionHandler.php:15
Stack trace:
#0 C:\Users\cheyod\Desktop\Home\WWW\bigbase\application\lib\exception\ExceptionHandler.php(15): think\Error::appError(4096, 'Argument 1 pass...', 'C:\\Users\\cheyod...', 15, Array)
#1 C:\Users\cheyod\Desktop\Home\WWW\bigbase\thinkphp\library\think\Error.php(47): app\lib\exception\ExceptionHandler->render(Object(think\exception\RouteNotFoundException))
#2 [internal function]: think\Error::appException(Object(think\exception\RouteNotFoundException))
#3 {main}
  thrown
---------------------------------------------------------------
[ 2017-08-27T12:33:41+08:00 ] 127.0.0.1 127.0.0.1 GET /index.php/api/v1/selProduct
[ error ] [1]Uncaught exception 'think\exception\ErrorException' with message 'Argument 1 passed to app\lib\exception\ExceptionHandler::render() must be an instance of think\Exception, instance of think\exception\RouteNotFoundException given, called in C:\Users\cheyod\Desktop\Home\WWW\bigbase\thinkphp\library\think\Error.php on line 47 and defined' in C:\Users\cheyod\Desktop\Home\WWW\bigbase\application\lib\exception\ExceptionHandler.php:15
Stack trace:
#0 C:\Users\cheyod\Desktop\Home\WWW\bigbase\application\lib\exception\ExceptionHandler.php(15): think\Error::appError(4096, 'Argument 1 pass...', 'C:\\Users\\cheyod...', 15, Array)
#1 C:\Users\cheyod\Desktop\Home\WWW\bigbase\thinkphp\library\think\Error.php(47): app\lib\exception\ExceptionHandler->render(Object(think\exception\RouteNotFoundException))
#2 [internal function]: think\Error::appException(Object(think\exception\RouteNotFoundException))
#3 {main}
  thrown
[ error ] Uncaught exception 'think\exception\ErrorException' with message 'Argument 1 passed to app\lib\exception\ExceptionHandler::render() must be an instance of think\Exception, instance of think\exception\RouteNotFoundException given, called in C:\Users\cheyod\Desktop\Home\WWW\bigbase\thinkphp\library\think\Error.php on line 47 and defined' in C:\Users\cheyod\Desktop\Home\WWW\bigbase\application\lib\exception\ExceptionHandler.php:15
Stack trace:
#0 C:\Users\cheyod\Desktop\Home\WWW\bigbase\application\lib\exception\ExceptionHandler.php(15): think\Error::appError(4096, 'Argument 1 pass...', 'C:\\Users\\cheyod...', 15, Array)
#1 C:\Users\cheyod\Desktop\Home\WWW\bigbase\thinkphp\library\think\Error.php(47): app\lib\exception\ExceptionHandler->render(Object(think\exception\RouteNotFoundException))
#2 [internal function]: think\Error::appException(Object(think\exception\RouteNotFoundException))
#3 {main}
  thrown
---------------------------------------------------------------
[ 2017-08-27T12:33:42+08:00 ] 127.0.0.1 127.0.0.1 GET /index.php/api/v1/selProduct
[ error ] [1]Uncaught exception 'think\exception\ErrorException' with message 'Argument 1 passed to app\lib\exception\ExceptionHandler::render() must be an instance of think\Exception, instance of think\exception\RouteNotFoundException given, called in C:\Users\cheyod\Desktop\Home\WWW\bigbase\thinkphp\library\think\Error.php on line 47 and defined' in C:\Users\cheyod\Desktop\Home\WWW\bigbase\application\lib\exception\ExceptionHandler.php:15
Stack trace:
#0 C:\Users\cheyod\Desktop\Home\WWW\bigbase\application\lib\exception\ExceptionHandler.php(15): think\Error::appError(4096, 'Argument 1 pass...', 'C:\\Users\\cheyod...', 15, Array)
#1 C:\Users\cheyod\Desktop\Home\WWW\bigbase\thinkphp\library\think\Error.php(47): app\lib\exception\ExceptionHandler->render(Object(think\exception\RouteNotFoundException))
#2 [internal function]: think\Error::appException(Object(think\exception\RouteNotFoundException))
#3 {main}
  thrown
[ error ] Uncaught exception 'think\exception\ErrorException' with message 'Argument 1 passed to app\lib\exception\ExceptionHandler::render() must be an instance of think\Exception, instance of think\exception\RouteNotFoundException given, called in C:\Users\cheyod\Desktop\Home\WWW\bigbase\thinkphp\library\think\Error.php on line 47 and defined' in C:\Users\cheyod\Desktop\Home\WWW\bigbase\application\lib\exception\ExceptionHandler.php:15
Stack trace:
#0 C:\Users\cheyod\Desktop\Home\WWW\bigbase\application\lib\exception\ExceptionHandler.php(15): think\Error::appError(4096, 'Argument 1 pass...', 'C:\\Users\\cheyod...', 15, Array)
#1 C:\Users\cheyod\Desktop\Home\WWW\bigbase\thinkphp\library\think\Error.php(47): app\lib\exception\ExceptionHandler->render(Object(think\exception\RouteNotFoundException))
#2 [internal function]: think\Error::appException(Object(think\exception\RouteNotFoundException))
#3 {main}
  thrown
---------------------------------------------------------------
[ 2017-08-27T12:33:42+08:00 ] 127.0.0.1 127.0.0.1 GET /index.php/api/v1/selProduct
[ error ] [1]Uncaught exception 'think\exception\ErrorException' with message 'Argument 1 passed to app\lib\exception\ExceptionHandler::render() must be an instance of think\Exception, instance of think\exception\RouteNotFoundException given, called in C:\Users\cheyod\Desktop\Home\WWW\bigbase\thinkphp\library\think\Error.php on line 47 and defined' in C:\Users\cheyod\Desktop\Home\WWW\bigbase\application\lib\exception\ExceptionHandler.php:15
Stack trace:
#0 C:\Users\cheyod\Desktop\Home\WWW\bigbase\application\lib\exception\ExceptionHandler.php(15): think\Error::appError(4096, 'Argument 1 pass...', 'C:\\Users\\cheyod...', 15, Array)
#1 C:\Users\cheyod\Desktop\Home\WWW\bigbase\thinkphp\library\think\Error.php(47): app\lib\exception\ExceptionHandler->render(Object(think\exception\RouteNotFoundException))
#2 [internal function]: think\Error::appException(Object(think\exception\RouteNotFoundException))
#3 {main}
  thrown
[ error ] Uncaught exception 'think\exception\ErrorException' with message 'Argument 1 passed to app\lib\exception\ExceptionHandler::render() must be an instance of think\Exception, instance of think\exception\RouteNotFoundException given, called in C:\Users\cheyod\Desktop\Home\WWW\bigbase\thinkphp\library\think\Error.php on line 47 and defined' in C:\Users\cheyod\Desktop\Home\WWW\bigbase\application\lib\exception\ExceptionHandler.php:15
Stack trace:
#0 C:\Users\cheyod\Desktop\Home\WWW\bigbase\application\lib\exception\ExceptionHandler.php(15): think\Error::appError(4096, 'Argument 1 pass...', 'C:\\Users\\cheyod...', 15, Array)
#1 C:\Users\cheyod\Desktop\Home\WWW\bigbase\thinkphp\library\think\Error.php(47): app\lib\exception\ExceptionHandler->render(Object(think\exception\RouteNotFoundException))
#2 [internal function]: think\Error::appException(Object(think\exception\RouteNotFoundException))
#3 {main}
  thrown
---------------------------------------------------------------
[ 2017-08-27T12:33:42+08:00 ] 127.0.0.1 127.0.0.1 GET /index.php/api/v1/selProduct
[ error ] [1]Uncaught exception 'think\exception\ErrorException' with message 'Argument 1 passed to app\lib\exception\ExceptionHandler::render() must be an instance of think\Exception, instance of think\exception\RouteNotFoundException given, called in C:\Users\cheyod\Desktop\Home\WWW\bigbase\thinkphp\library\think\Error.php on line 47 and defined' in C:\Users\cheyod\Desktop\Home\WWW\bigbase\application\lib\exception\ExceptionHandler.php:15
Stack trace:
#0 C:\Users\cheyod\Desktop\Home\WWW\bigbase\application\lib\exception\ExceptionHandler.php(15): think\Error::appError(4096, 'Argument 1 pass...', 'C:\\Users\\cheyod...', 15, Array)
#1 C:\Users\cheyod\Desktop\Home\WWW\bigbase\thinkphp\library\think\Error.php(47): app\lib\exception\ExceptionHandler->render(Object(think\exception\RouteNotFoundException))
#2 [internal function]: think\Error::appException(Object(think\exception\RouteNotFoundException))
#3 {main}
  thrown
[ error ] Uncaught exception 'think\exception\ErrorException' with message 'Argument 1 passed to app\lib\exception\ExceptionHandler::render() must be an instance of think\Exception, instance of think\exception\RouteNotFoundException given, called in C:\Users\cheyod\Desktop\Home\WWW\bigbase\thinkphp\library\think\Error.php on line 47 and defined' in C:\Users\cheyod\Desktop\Home\WWW\bigbase\application\lib\exception\ExceptionHandler.php:15
Stack trace:
#0 C:\Users\cheyod\Desktop\Home\WWW\bigbase\application\lib\exception\ExceptionHandler.php(15): think\Error::appError(4096, 'Argument 1 pass...', 'C:\\Users\\cheyod...', 15, Array)
#1 C:\Users\cheyod\Desktop\Home\WWW\bigbase\thinkphp\library\think\Error.php(47): app\lib\exception\ExceptionHandler->render(Object(think\exception\RouteNotFoundException))
#2 [internal function]: think\Error::appException(Object(think\exception\RouteNotFoundException))
#3 {main}
  thrown
---------------------------------------------------------------
[ 2017-08-27T12:47:36+08:00 ] 127.0.0.1 127.0.0.1 GET /index.php/api/v1/selProduct
[ error ] [1]Uncaught exception 'think\exception\ErrorException' with message 'Argument 1 passed to app\lib\exception\ExceptionHandler::render() must be an instance of think\Exception, instance of think\exception\RouteNotFoundException given, called in C:\Users\cheyod\Desktop\Home\WWW\bigbase\thinkphp\library\think\Error.php on line 47 and defined' in C:\Users\cheyod\Desktop\Home\WWW\bigbase\application\lib\exception\ExceptionHandler.php:15
Stack trace:
#0 C:\Users\cheyod\Desktop\Home\WWW\bigbase\application\lib\exception\ExceptionHandler.php(15): think\Error::appError(4096, 'Argument 1 pass...', 'C:\\Users\\cheyod...', 15, Array)
#1 C:\Users\cheyod\Desktop\Home\WWW\bigbase\thinkphp\library\think\Error.php(47): app\lib\exception\ExceptionHandler->render(Object(think\exception\RouteNotFoundException))
#2 [internal function]: think\Error::appException(Object(think\exception\RouteNotFoundException))
#3 {main}
  thrown
[ error ] Uncaught exception 'think\exception\ErrorException' with message 'Argument 1 passed to app\lib\exception\ExceptionHandler::render() must be an instance of think\Exception, instance of think\exception\RouteNotFoundException given, called in C:\Users\cheyod\Desktop\Home\WWW\bigbase\thinkphp\library\think\Error.php on line 47 and defined' in C:\Users\cheyod\Desktop\Home\WWW\bigbase\application\lib\exception\ExceptionHandler.php:15
Stack trace:
#0 C:\Users\cheyod\Desktop\Home\WWW\bigbase\application\lib\exception\ExceptionHandler.php(15): think\Error::appError(4096, 'Argument 1 pass...', 'C:\\Users\\cheyod...', 15, Array)
#1 C:\Users\cheyod\Desktop\Home\WWW\bigbase\thinkphp\library\think\Error.php(47): app\lib\exception\ExceptionHandler->render(Object(think\exception\RouteNotFoundException))
#2 [internal function]: think\Error::appException(Object(think\exception\RouteNotFoundException))
#3 {main}
  thrown
---------------------------------------------------------------
[ 2017-08-27T12:47:37+08:00 ] 127.0.0.1 127.0.0.1 GET /index.php/api/v1/selProduct
[ error ] [1]Uncaught exception 'think\exception\ErrorException' with message 'Argument 1 passed to app\lib\exception\ExceptionHandler::render() must be an instance of think\Exception, instance of think\exception\RouteNotFoundException given, called in C:\Users\cheyod\Desktop\Home\WWW\bigbase\thinkphp\library\think\Error.php on line 47 and defined' in C:\Users\cheyod\Desktop\Home\WWW\bigbase\application\lib\exception\ExceptionHandler.php:15
Stack trace:
#0 C:\Users\cheyod\Desktop\Home\WWW\bigbase\application\lib\exception\ExceptionHandler.php(15): think\Error::appError(4096, 'Argument 1 pass...', 'C:\\Users\\cheyod...', 15, Array)
#1 C:\Users\cheyod\Desktop\Home\WWW\bigbase\thinkphp\library\think\Error.php(47): app\lib\exception\ExceptionHandler->render(Object(think\exception\RouteNotFoundException))
#2 [internal function]: think\Error::appException(Object(think\exception\RouteNotFoundException))
#3 {main}
  thrown
[ error ] Uncaught exception 'think\exception\ErrorException' with message 'Argument 1 passed to app\lib\exception\ExceptionHandler::render() must be an instance of think\Exception, instance of think\exception\RouteNotFoundException given, called in C:\Users\cheyod\Desktop\Home\WWW\bigbase\thinkphp\library\think\Error.php on line 47 and defined' in C:\Users\cheyod\Desktop\Home\WWW\bigbase\application\lib\exception\ExceptionHandler.php:15
Stack trace:
#0 C:\Users\cheyod\Desktop\Home\WWW\bigbase\application\lib\exception\ExceptionHandler.php(15): think\Error::appError(4096, 'Argument 1 pass...', 'C:\\Users\\cheyod...', 15, Array)
#1 C:\Users\cheyod\Desktop\Home\WWW\bigbase\thinkphp\library\think\Error.php(47): app\lib\exception\ExceptionHandler->render(Object(think\exception\RouteNotFoundException))
#2 [internal function]: think\Error::appException(Object(think\exception\RouteNotFoundException))
#3 {main}
  thrown
---------------------------------------------------------------
[ 2017-08-27T12:48:57+08:00 ] 127.0.0.1 127.0.0.1 GET /index.php/api/v1/selProduct
[ error ] [1]Uncaught exception 'think\exception\ErrorException' with message 'Argument 1 passed to app\lib\exception\ExceptionHandler::render() must be an instance of think\Exception, instance of think\exception\RouteNotFoundException given, called in C:\Users\cheyod\Desktop\Home\WWW\bigbase\thinkphp\library\think\Error.php on line 47 and defined' in C:\Users\cheyod\Desktop\Home\WWW\bigbase\application\lib\exception\ExceptionHandler.php:16
Stack trace:
#0 C:\Users\cheyod\Desktop\Home\WWW\bigbase\application\lib\exception\ExceptionHandler.php(16): think\Error::appError(4096, 'Argument 1 pass...', 'C:\\Users\\cheyod...', 16, Array)
#1 C:\Users\cheyod\Desktop\Home\WWW\bigbase\thinkphp\library\think\Error.php(47): app\lib\exception\ExceptionHandler->render(Object(think\exception\RouteNotFoundException))
#2 [internal function]: think\Error::appException(Object(think\exception\RouteNotFoundException))
#3 {main}
  thrown
[ error ] Uncaught exception 'think\exception\ErrorException' with message 'Argument 1 passed to app\lib\exception\ExceptionHandler::render() must be an instance of think\Exception, instance of think\exception\RouteNotFoundException given, called in C:\Users\cheyod\Desktop\Home\WWW\bigbase\thinkphp\library\think\Error.php on line 47 and defined' in C:\Users\cheyod\Desktop\Home\WWW\bigbase\application\lib\exception\ExceptionHandler.php:16
Stack trace:
#0 C:\Users\cheyod\Desktop\Home\WWW\bigbase\application\lib\exception\ExceptionHandler.php(16): think\Error::appError(4096, 'Argument 1 pass...', 'C:\\Users\\cheyod...', 16, Array)
#1 C:\Users\cheyod\Desktop\Home\WWW\bigbase\thinkphp\library\think\Error.php(47): app\lib\exception\ExceptionHandler->render(Object(think\exception\RouteNotFoundException))
#2 [internal function]: think\Error::appException(Object(think\exception\RouteNotFoundException))
#3 {main}
  thrown
---------------------------------------------------------------
[ 2017-08-27T12:48:58+08:00 ] 127.0.0.1 127.0.0.1 GET /index.php/api/v1/selProduct
[ error ] [1]Uncaught exception 'think\exception\ErrorException' with message 'Argument 1 passed to app\lib\exception\ExceptionHandler::render() must be an instance of think\Exception, instance of think\exception\RouteNotFoundException given, called in C:\Users\cheyod\Desktop\Home\WWW\bigbase\thinkphp\library\think\Error.php on line 47 and defined' in C:\Users\cheyod\Desktop\Home\WWW\bigbase\application\lib\exception\ExceptionHandler.php:16
Stack trace:
#0 C:\Users\cheyod\Desktop\Home\WWW\bigbase\application\lib\exception\ExceptionHandler.php(16): think\Error::appError(4096, 'Argument 1 pass...', 'C:\\Users\\cheyod...', 16, Array)
#1 C:\Users\cheyod\Desktop\Home\WWW\bigbase\thinkphp\library\think\Error.php(47): app\lib\exception\ExceptionHandler->render(Object(think\exception\RouteNotFoundException))
#2 [internal function]: think\Error::appException(Object(think\exception\RouteNotFoundException))
#3 {main}
  thrown
[ error ] Uncaught exception 'think\exception\ErrorException' with message 'Argument 1 passed to app\lib\exception\ExceptionHandler::render() must be an instance of think\Exception, instance of think\exception\RouteNotFoundException given, called in C:\Users\cheyod\Desktop\Home\WWW\bigbase\thinkphp\library\think\Error.php on line 47 and defined' in C:\Users\cheyod\Desktop\Home\WWW\bigbase\application\lib\exception\ExceptionHandler.php:16
Stack trace:
#0 C:\Users\cheyod\Desktop\Home\WWW\bigbase\application\lib\exception\ExceptionHandler.php(16): think\Error::appError(4096, 'Argument 1 pass...', 'C:\\Users\\cheyod...', 16, Array)
#1 C:\Users\cheyod\Desktop\Home\WWW\bigbase\thinkphp\library\think\Error.php(47): app\lib\exception\ExceptionHandler->render(Object(think\exception\RouteNotFoundException))
#2 [internal function]: think\Error::appException(Object(think\exception\RouteNotFoundException))
#3 {main}
  thrown
---------------------------------------------------------------
[ 2017-08-27T12:48:59+08:00 ] 127.0.0.1 127.0.0.1 GET /index.php/api/v1/selProduct
[ error ] [1]Uncaught exception 'think\exception\ErrorException' with message 'Argument 1 passed to app\lib\exception\ExceptionHandler::render() must be an instance of think\Exception, instance of think\exception\RouteNotFoundException given, called in C:\Users\cheyod\Desktop\Home\WWW\bigbase\thinkphp\library\think\Error.php on line 47 and defined' in C:\Users\cheyod\Desktop\Home\WWW\bigbase\application\lib\exception\ExceptionHandler.php:16
Stack trace:
#0 C:\Users\cheyod\Desktop\Home\WWW\bigbase\application\lib\exception\ExceptionHandler.php(16): think\Error::appError(4096, 'Argument 1 pass...', 'C:\\Users\\cheyod...', 16, Array)
#1 C:\Users\cheyod\Desktop\Home\WWW\bigbase\thinkphp\library\think\Error.php(47): app\lib\exception\ExceptionHandler->render(Object(think\exception\RouteNotFoundException))
#2 [internal function]: think\Error::appException(Object(think\exception\RouteNotFoundException))
#3 {main}
  thrown
[ error ] Uncaught exception 'think\exception\ErrorException' with message 'Argument 1 passed to app\lib\exception\ExceptionHandler::render() must be an instance of think\Exception, instance of think\exception\RouteNotFoundException given, called in C:\Users\cheyod\Desktop\Home\WWW\bigbase\thinkphp\library\think\Error.php on line 47 and defined' in C:\Users\cheyod\Desktop\Home\WWW\bigbase\application\lib\exception\ExceptionHandler.php:16
Stack trace:
#0 C:\Users\cheyod\Desktop\Home\WWW\bigbase\application\lib\exception\ExceptionHandler.php(16): think\Error::appError(4096, 'Argument 1 pass...', 'C:\\Users\\cheyod...', 16, Array)
#1 C:\Users\cheyod\Desktop\Home\WWW\bigbase\thinkphp\library\think\Error.php(47): app\lib\exception\ExceptionHandler->render(Object(think\exception\RouteNotFoundException))
#2 [internal function]: think\Error::appException(Object(think\exception\RouteNotFoundException))
#3 {main}
  thrown
---------------------------------------------------------------
[ 2017-08-27T12:48:59+08:00 ] 127.0.0.1 127.0.0.1 GET /index.php/api/v1/selProduct
[ error ] [1]Uncaught exception 'think\exception\ErrorException' with message 'Argument 1 passed to app\lib\exception\ExceptionHandler::render() must be an instance of think\Exception, instance of think\exception\RouteNotFoundException given, called in C:\Users\cheyod\Desktop\Home\WWW\bigbase\thinkphp\library\think\Error.php on line 47 and defined' in C:\Users\cheyod\Desktop\Home\WWW\bigbase\application\lib\exception\ExceptionHandler.php:16
Stack trace:
#0 C:\Users\cheyod\Desktop\Home\WWW\bigbase\application\lib\exception\ExceptionHandler.php(16): think\Error::appError(4096, 'Argument 1 pass...', 'C:\\Users\\cheyod...', 16, Array)
#1 C:\Users\cheyod\Desktop\Home\WWW\bigbase\thinkphp\library\think\Error.php(47): app\lib\exception\ExceptionHandler->render(Object(think\exception\RouteNotFoundException))
#2 [internal function]: think\Error::appException(Object(think\exception\RouteNotFoundException))
#3 {main}
  thrown
[ error ] Uncaught exception 'think\exception\ErrorException' with message 'Argument 1 passed to app\lib\exception\ExceptionHandler::render() must be an instance of think\Exception, instance of think\exception\RouteNotFoundException given, called in C:\Users\cheyod\Desktop\Home\WWW\bigbase\thinkphp\library\think\Error.php on line 47 and defined' in C:\Users\cheyod\Desktop\Home\WWW\bigbase\application\lib\exception\ExceptionHandler.php:16
Stack trace:
#0 C:\Users\cheyod\Desktop\Home\WWW\bigbase\application\lib\exception\ExceptionHandler.php(16): think\Error::appError(4096, 'Argument 1 pass...', 'C:\\Users\\cheyod...', 16, Array)
#1 C:\Users\cheyod\Desktop\Home\WWW\bigbase\thinkphp\library\think\Error.php(47): app\lib\exception\ExceptionHandler->render(Object(think\exception\RouteNotFoundException))
#2 [internal function]: think\Error::appException(Object(think\exception\RouteNotFoundException))
#3 {main}
  thrown
---------------------------------------------------------------
[ 2017-08-27T12:49:01+08:00 ] 127.0.0.1 127.0.0.1 GET /index.php/api/v1/selProduct
[ error ] [1]Uncaught exception 'think\exception\ErrorException' with message 'Argument 1 passed to app\lib\exception\ExceptionHandler::render() must be an instance of think\Exception, instance of think\exception\RouteNotFoundException given, called in C:\Users\cheyod\Desktop\Home\WWW\bigbase\thinkphp\library\think\Error.php on line 47 and defined' in C:\Users\cheyod\Desktop\Home\WWW\bigbase\application\lib\exception\ExceptionHandler.php:16
Stack trace:
#0 C:\Users\cheyod\Desktop\Home\WWW\bigbase\application\lib\exception\ExceptionHandler.php(16): think\Error::appError(4096, 'Argument 1 pass...', 'C:\\Users\\cheyod...', 16, Array)
#1 C:\Users\cheyod\Desktop\Home\WWW\bigbase\thinkphp\library\think\Error.php(47): app\lib\exception\ExceptionHandler->render(Object(think\exception\RouteNotFoundException))
#2 [internal function]: think\Error::appException(Object(think\exception\RouteNotFoundException))
#3 {main}
  thrown
[ error ] Uncaught exception 'think\exception\ErrorException' with message 'Argument 1 passed to app\lib\exception\ExceptionHandler::render() must be an instance of think\Exception, instance of think\exception\RouteNotFoundException given, called in C:\Users\cheyod\Desktop\Home\WWW\bigbase\thinkphp\library\think\Error.php on line 47 and defined' in C:\Users\cheyod\Desktop\Home\WWW\bigbase\application\lib\exception\ExceptionHandler.php:16
Stack trace:
#0 C:\Users\cheyod\Desktop\Home\WWW\bigbase\application\lib\exception\ExceptionHandler.php(16): think\Error::appError(4096, 'Argument 1 pass...', 'C:\\Users\\cheyod...', 16, Array)
#1 C:\Users\cheyod\Desktop\Home\WWW\bigbase\thinkphp\library\think\Error.php(47): app\lib\exception\ExceptionHandler->render(Object(think\exception\RouteNotFoundException))
#2 [internal function]: think\Error::appException(Object(think\exception\RouteNotFoundException))
#3 {main}
  thrown
---------------------------------------------------------------
[ 2017-08-27T14:11:37+08:00 ] 127.0.0.1 127.0.0.1 GET /index.php/v1/product
[ error ] [1]Uncaught exception 'think\exception\ErrorException' with message 'Argument 1 passed to app\lib\exception\ExceptionHandler::render() must be an instance of think\Exception, instance of think\exception\RouteNotFoundException given, called in C:\Users\cheyod\Desktop\Home\WWW\bigbase\thinkphp\library\think\Error.php on line 47 and defined' in C:\Users\cheyod\Desktop\Home\WWW\bigbase\application\lib\exception\ExceptionHandler.php:15
Stack trace:
#0 C:\Users\cheyod\Desktop\Home\WWW\bigbase\application\lib\exception\ExceptionHandler.php(15): think\Error::appError(4096, 'Argument 1 pass...', 'C:\\Users\\cheyod...', 15, Array)
#1 C:\Users\cheyod\Desktop\Home\WWW\bigbase\thinkphp\library\think\Error.php(47): app\lib\exception\ExceptionHandler->render(Object(think\exception\RouteNotFoundException))
#2 [internal function]: think\Error::appException(Object(think\exception\RouteNotFoundException))
#3 {main}
  thrown
[ error ] Uncaught exception 'think\exception\ErrorException' with message 'Argument 1 passed to app\lib\exception\ExceptionHandler::render() must be an instance of think\Exception, instance of think\exception\RouteNotFoundException given, called in C:\Users\cheyod\Desktop\Home\WWW\bigbase\thinkphp\library\think\Error.php on line 47 and defined' in C:\Users\cheyod\Desktop\Home\WWW\bigbase\application\lib\exception\ExceptionHandler.php:15
Stack trace:
#0 C:\Users\cheyod\Desktop\Home\WWW\bigbase\application\lib\exception\ExceptionHandler.php(15): think\Error::appError(4096, 'Argument 1 pass...', 'C:\\Users\\cheyod...', 15, Array)
#1 C:\Users\cheyod\Desktop\Home\WWW\bigbase\thinkphp\library\think\Error.php(47): app\lib\exception\ExceptionHandler->render(Object(think\exception\RouteNotFoundException))
#2 [internal function]: think\Error::appException(Object(think\exception\RouteNotFoundException))
#3 {main}
  thrown
---------------------------------------------------------------
[ 2017-08-27T14:11:38+08:00 ] 127.0.0.1 127.0.0.1 GET /index.php/v1/product
[ error ] [1]Uncaught exception 'think\exception\ErrorException' with message 'Argument 1 passed to app\lib\exception\ExceptionHandler::render() must be an instance of think\Exception, instance of think\exception\RouteNotFoundException given, called in C:\Users\cheyod\Desktop\Home\WWW\bigbase\thinkphp\library\think\Error.php on line 47 and defined' in C:\Users\cheyod\Desktop\Home\WWW\bigbase\application\lib\exception\ExceptionHandler.php:15
Stack trace:
#0 C:\Users\cheyod\Desktop\Home\WWW\bigbase\application\lib\exception\ExceptionHandler.php(15): think\Error::appError(4096, 'Argument 1 pass...', 'C:\\Users\\cheyod...', 15, Array)
#1 C:\Users\cheyod\Desktop\Home\WWW\bigbase\thinkphp\library\think\Error.php(47): app\lib\exception\ExceptionHandler->render(Object(think\exception\RouteNotFoundException))
#2 [internal function]: think\Error::appException(Object(think\exception\RouteNotFoundException))
#3 {main}
  thrown
[ error ] Uncaught exception 'think\exception\ErrorException' with message 'Argument 1 passed to app\lib\exception\ExceptionHandler::render() must be an instance of think\Exception, instance of think\exception\RouteNotFoundException given, called in C:\Users\cheyod\Desktop\Home\WWW\bigbase\thinkphp\library\think\Error.php on line 47 and defined' in C:\Users\cheyod\Desktop\Home\WWW\bigbase\application\lib\exception\ExceptionHandler.php:15
Stack trace:
#0 C:\Users\cheyod\Desktop\Home\WWW\bigbase\application\lib\exception\ExceptionHandler.php(15): think\Error::appError(4096, 'Argument 1 pass...', 'C:\\Users\\cheyod...', 15, Array)
#1 C:\Users\cheyod\Desktop\Home\WWW\bigbase\thinkphp\library\think\Error.php(47): app\lib\exception\ExceptionHandler->render(Object(think\exception\RouteNotFoundException))
#2 [internal function]: think\Error::appException(Object(think\exception\RouteNotFoundException))
#3 {main}
  thrown
---------------------------------------------------------------
[ 2017-08-27T14:12:56+08:00 ] 127.0.0.1 127.0.0.1 GET /index.php/v1/product
[ error ] [1]Uncaught exception 'think\exception\ErrorException' with message 'Argument 1 passed to app\lib\exception\ExceptionHandler::render() must be an instance of think\Exception, instance of think\exception\RouteNotFoundException given, called in C:\Users\cheyod\Desktop\Home\WWW\bigbase\thinkphp\library\think\Error.php on line 47 and defined' in C:\Users\cheyod\Desktop\Home\WWW\bigbase\application\lib\exception\ExceptionHandler.php:15
Stack trace:
#0 C:\Users\cheyod\Desktop\Home\WWW\bigbase\application\lib\exception\ExceptionHandler.php(15): think\Error::appError(4096, 'Argument 1 pass...', 'C:\\Users\\cheyod...', 15, Array)
#1 C:\Users\cheyod\Desktop\Home\WWW\bigbase\thinkphp\library\think\Error.php(47): app\lib\exception\ExceptionHandler->render(Object(think\exception\RouteNotFoundException))
#2 [internal function]: think\Error::appException(Object(think\exception\RouteNotFoundException))
#3 {main}
  thrown
[ error ] Uncaught exception 'think\exception\ErrorException' with message 'Argument 1 passed to app\lib\exception\ExceptionHandler::render() must be an instance of think\Exception, instance of think\exception\RouteNotFoundException given, called in C:\Users\cheyod\Desktop\Home\WWW\bigbase\thinkphp\library\think\Error.php on line 47 and defined' in C:\Users\cheyod\Desktop\Home\WWW\bigbase\application\lib\exception\ExceptionHandler.php:15
Stack trace:
#0 C:\Users\cheyod\Desktop\Home\WWW\bigbase\application\lib\exception\ExceptionHandler.php(15): think\Error::appError(4096, 'Argument 1 pass...', 'C:\\Users\\cheyod...', 15, Array)
#1 C:\Users\cheyod\Desktop\Home\WWW\bigbase\thinkphp\library\think\Error.php(47): app\lib\exception\ExceptionHandler->render(Object(think\exception\RouteNotFoundException))
#2 [internal function]: think\Error::appException(Object(think\exception\RouteNotFoundException))
#3 {main}
  thrown
---------------------------------------------------------------
[ 2017-08-27T14:15:13+08:00 ] 127.0.0.1 127.0.0.1 GET /index.php/v1/product
[ error ] [1]Uncaught exception 'think\exception\ErrorException' with message 'Argument 1 passed to app\lib\exception\ExceptionHandler::render() must be an instance of think\Exception, instance of think\exception\RouteNotFoundException given, called in C:\Users\cheyod\Desktop\Home\WWW\bigbase\thinkphp\library\think\Error.php on line 47 and defined' in C:\Users\cheyod\Desktop\Home\WWW\bigbase\application\lib\exception\ExceptionHandler.php:15
Stack trace:
#0 C:\Users\cheyod\Desktop\Home\WWW\bigbase\application\lib\exception\ExceptionHandler.php(15): think\Error::appError(4096, 'Argument 1 pass...', 'C:\\Users\\cheyod...', 15, Array)
#1 C:\Users\cheyod\Desktop\Home\WWW\bigbase\thinkphp\library\think\Error.php(47): app\lib\exception\ExceptionHandler->render(Object(think\exception\RouteNotFoundException))
#2 [internal function]: think\Error::appException(Object(think\exception\RouteNotFoundException))
#3 {main}
  thrown
[ error ] Uncaught exception 'think\exception\ErrorException' with message 'Argument 1 passed to app\lib\exception\ExceptionHandler::render() must be an instance of think\Exception, instance of think\exception\RouteNotFoundException given, called in C:\Users\cheyod\Desktop\Home\WWW\bigbase\thinkphp\library\think\Error.php on line 47 and defined' in C:\Users\cheyod\Desktop\Home\WWW\bigbase\application\lib\exception\ExceptionHandler.php:15
Stack trace:
#0 C:\Users\cheyod\Desktop\Home\WWW\bigbase\application\lib\exception\ExceptionHandler.php(15): think\Error::appError(4096, 'Argument 1 pass...', 'C:\\Users\\cheyod...', 15, Array)
#1 C:\Users\cheyod\Desktop\Home\WWW\bigbase\thinkphp\library\think\Error.php(47): app\lib\exception\ExceptionHandler->render(Object(think\exception\RouteNotFoundException))
#2 [internal function]: think\Error::appException(Object(think\exception\RouteNotFoundException))
#3 {main}
  thrown
---------------------------------------------------------------
[ 2017-08-27T14:15:14+08:00 ] 127.0.0.1 127.0.0.1 GET /index.php/v1/product
[ error ] [1]Uncaught exception 'think\exception\ErrorException' with message 'Argument 1 passed to app\lib\exception\ExceptionHandler::render() must be an instance of think\Exception, instance of think\exception\RouteNotFoundException given, called in C:\Users\cheyod\Desktop\Home\WWW\bigbase\thinkphp\library\think\Error.php on line 47 and defined' in C:\Users\cheyod\Desktop\Home\WWW\bigbase\application\lib\exception\ExceptionHandler.php:15
Stack trace:
#0 C:\Users\cheyod\Desktop\Home\WWW\bigbase\application\lib\exception\ExceptionHandler.php(15): think\Error::appError(4096, 'Argument 1 pass...', 'C:\\Users\\cheyod...', 15, Array)
#1 C:\Users\cheyod\Desktop\Home\WWW\bigbase\thinkphp\library\think\Error.php(47): app\lib\exception\ExceptionHandler->render(Object(think\exception\RouteNotFoundException))
#2 [internal function]: think\Error::appException(Object(think\exception\RouteNotFoundException))
#3 {main}
  thrown
[ error ] Uncaught exception 'think\exception\ErrorException' with message 'Argument 1 passed to app\lib\exception\ExceptionHandler::render() must be an instance of think\Exception, instance of think\exception\RouteNotFoundException given, called in C:\Users\cheyod\Desktop\Home\WWW\bigbase\thinkphp\library\think\Error.php on line 47 and defined' in C:\Users\cheyod\Desktop\Home\WWW\bigbase\application\lib\exception\ExceptionHandler.php:15
Stack trace:
#0 C:\Users\cheyod\Desktop\Home\WWW\bigbase\application\lib\exception\ExceptionHandler.php(15): think\Error::appError(4096, 'Argument 1 pass...', 'C:\\Users\\cheyod...', 15, Array)
#1 C:\Users\cheyod\Desktop\Home\WWW\bigbase\thinkphp\library\think\Error.php(47): app\lib\exception\ExceptionHandler->render(Object(think\exception\RouteNotFoundException))
#2 [internal function]: think\Error::appException(Object(think\exception\RouteNotFoundException))
#3 {main}
  thrown
---------------------------------------------------------------
[ 2017-08-27T14:15:27+08:00 ] 127.0.0.1 127.0.0.1 GET /index.php/v1/product
[ error ] [1]Uncaught exception 'think\exception\ErrorException' with message 'Argument 1 passed to app\lib\exception\ExceptionHandler::render() must be an instance of think\Exception, instance of think\exception\RouteNotFoundException given, called in C:\Users\cheyod\Desktop\Home\WWW\bigbase\thinkphp\library\think\Error.php on line 47 and defined' in C:\Users\cheyod\Desktop\Home\WWW\bigbase\application\lib\exception\ExceptionHandler.php:15
Stack trace:
#0 C:\Users\cheyod\Desktop\Home\WWW\bigbase\application\lib\exception\ExceptionHandler.php(15): think\Error::appError(4096, 'Argument 1 pass...', 'C:\\Users\\cheyod...', 15, Array)
#1 C:\Users\cheyod\Desktop\Home\WWW\bigbase\thinkphp\library\think\Error.php(47): app\lib\exception\ExceptionHandler->render(Object(think\exception\RouteNotFoundException))
#2 [internal function]: think\Error::appException(Object(think\exception\RouteNotFoundException))
#3 {main}
  thrown
[ error ] Uncaught exception 'think\exception\ErrorException' with message 'Argument 1 passed to app\lib\exception\ExceptionHandler::render() must be an instance of think\Exception, instance of think\exception\RouteNotFoundException given, called in C:\Users\cheyod\Desktop\Home\WWW\bigbase\thinkphp\library\think\Error.php on line 47 and defined' in C:\Users\cheyod\Desktop\Home\WWW\bigbase\application\lib\exception\ExceptionHandler.php:15
Stack trace:
#0 C:\Users\cheyod\Desktop\Home\WWW\bigbase\application\lib\exception\ExceptionHandler.php(15): think\Error::appError(4096, 'Argument 1 pass...', 'C:\\Users\\cheyod...', 15, Array)
#1 C:\Users\cheyod\Desktop\Home\WWW\bigbase\thinkphp\library\think\Error.php(47): app\lib\exception\ExceptionHandler->render(Object(think\exception\RouteNotFoundException))
#2 [internal function]: think\Error::appException(Object(think\exception\RouteNotFoundException))
#3 {main}
  thrown
---------------------------------------------------------------
[ 2017-08-27T14:15:27+08:00 ] 127.0.0.1 127.0.0.1 GET /index.php/v1/product
[ error ] [1]Uncaught exception 'think\exception\ErrorException' with message 'Argument 1 passed to app\lib\exception\ExceptionHandler::render() must be an instance of think\Exception, instance of think\exception\RouteNotFoundException given, called in C:\Users\cheyod\Desktop\Home\WWW\bigbase\thinkphp\library\think\Error.php on line 47 and defined' in C:\Users\cheyod\Desktop\Home\WWW\bigbase\application\lib\exception\ExceptionHandler.php:15
Stack trace:
#0 C:\Users\cheyod\Desktop\Home\WWW\bigbase\application\lib\exception\ExceptionHandler.php(15): think\Error::appError(4096, 'Argument 1 pass...', 'C:\\Users\\cheyod...', 15, Array)
#1 C:\Users\cheyod\Desktop\Home\WWW\bigbase\thinkphp\library\think\Error.php(47): app\lib\exception\ExceptionHandler->render(Object(think\exception\RouteNotFoundException))
#2 [internal function]: think\Error::appException(Object(think\exception\RouteNotFoundException))
#3 {main}
  thrown
[ error ] Uncaught exception 'think\exception\ErrorException' with message 'Argument 1 passed to app\lib\exception\ExceptionHandler::render() must be an instance of think\Exception, instance of think\exception\RouteNotFoundException given, called in C:\Users\cheyod\Desktop\Home\WWW\bigbase\thinkphp\library\think\Error.php on line 47 and defined' in C:\Users\cheyod\Desktop\Home\WWW\bigbase\application\lib\exception\ExceptionHandler.php:15
Stack trace:
#0 C:\Users\cheyod\Desktop\Home\WWW\bigbase\application\lib\exception\ExceptionHandler.php(15): think\Error::appError(4096, 'Argument 1 pass...', 'C:\\Users\\cheyod...', 15, Array)
#1 C:\Users\cheyod\Desktop\Home\WWW\bigbase\thinkphp\library\think\Error.php(47): app\lib\exception\ExceptionHandler->render(Object(think\exception\RouteNotFoundException))
#2 [internal function]: think\Error::appException(Object(think\exception\RouteNotFoundException))
#3 {main}
  thrown
---------------------------------------------------------------
[ 2017-08-27T14:15:47+08:00 ] 127.0.0.1 127.0.0.1 GET /index.php/v1/product
[ error ] [1]Uncaught exception 'think\exception\ErrorException' with message 'Argument 1 passed to app\lib\exception\ExceptionHandler::render() must be an instance of think\Exception, instance of think\exception\RouteNotFoundException given, called in C:\Users\cheyod\Desktop\Home\WWW\bigbase\thinkphp\library\think\Error.php on line 47 and defined' in C:\Users\cheyod\Desktop\Home\WWW\bigbase\application\lib\exception\ExceptionHandler.php:15
Stack trace:
#0 C:\Users\cheyod\Desktop\Home\WWW\bigbase\application\lib\exception\ExceptionHandler.php(15): think\Error::appError(4096, 'Argument 1 pass...', 'C:\\Users\\cheyod...', 15, Array)
#1 C:\Users\cheyod\Desktop\Home\WWW\bigbase\thinkphp\library\think\Error.php(47): app\lib\exception\ExceptionHandler->render(Object(think\exception\RouteNotFoundException))
#2 [internal function]: think\Error::appException(Object(think\exception\RouteNotFoundException))
#3 {main}
  thrown
[ error ] Uncaught exception 'think\exception\ErrorException' with message 'Argument 1 passed to app\lib\exception\ExceptionHandler::render() must be an instance of think\Exception, instance of think\exception\RouteNotFoundException given, called in C:\Users\cheyod\Desktop\Home\WWW\bigbase\thinkphp\library\think\Error.php on line 47 and defined' in C:\Users\cheyod\Desktop\Home\WWW\bigbase\application\lib\exception\ExceptionHandler.php:15
Stack trace:
#0 C:\Users\cheyod\Desktop\Home\WWW\bigbase\application\lib\exception\ExceptionHandler.php(15): think\Error::appError(4096, 'Argument 1 pass...', 'C:\\Users\\cheyod...', 15, Array)
#1 C:\Users\cheyod\Desktop\Home\WWW\bigbase\thinkphp\library\think\Error.php(47): app\lib\exception\ExceptionHandler->render(Object(think\exception\RouteNotFoundException))
#2 [internal function]: think\Error::appException(Object(think\exception\RouteNotFoundException))
#3 {main}
  thrown
---------------------------------------------------------------
[ 2017-08-27T14:15:47+08:00 ] 127.0.0.1 127.0.0.1 GET /index.php/v1/product
[ error ] [1]Uncaught exception 'think\exception\ErrorException' with message 'Argument 1 passed to app\lib\exception\ExceptionHandler::render() must be an instance of think\Exception, instance of think\exception\RouteNotFoundException given, called in C:\Users\cheyod\Desktop\Home\WWW\bigbase\thinkphp\library\think\Error.php on line 47 and defined' in C:\Users\cheyod\Desktop\Home\WWW\bigbase\application\lib\exception\ExceptionHandler.php:15
Stack trace:
#0 C:\Users\cheyod\Desktop\Home\WWW\bigbase\application\lib\exception\ExceptionHandler.php(15): think\Error::appError(4096, 'Argument 1 pass...', 'C:\\Users\\cheyod...', 15, Array)
#1 C:\Users\cheyod\Desktop\Home\WWW\bigbase\thinkphp\library\think\Error.php(47): app\lib\exception\ExceptionHandler->render(Object(think\exception\RouteNotFoundException))
#2 [internal function]: think\Error::appException(Object(think\exception\RouteNotFoundException))
#3 {main}
  thrown
[ error ] Uncaught exception 'think\exception\ErrorException' with message 'Argument 1 passed to app\lib\exception\ExceptionHandler::render() must be an instance of think\Exception, instance of think\exception\RouteNotFoundException given, called in C:\Users\cheyod\Desktop\Home\WWW\bigbase\thinkphp\library\think\Error.php on line 47 and defined' in C:\Users\cheyod\Desktop\Home\WWW\bigbase\application\lib\exception\ExceptionHandler.php:15
Stack trace:
#0 C:\Users\cheyod\Desktop\Home\WWW\bigbase\application\lib\exception\ExceptionHandler.php(15): think\Error::appError(4096, 'Argument 1 pass...', 'C:\\Users\\cheyod...', 15, Array)
#1 C:\Users\cheyod\Desktop\Home\WWW\bigbase\thinkphp\library\think\Error.php(47): app\lib\exception\ExceptionHandler->render(Object(think\exception\RouteNotFoundException))
#2 [internal function]: think\Error::appException(Object(think\exception\RouteNotFoundException))
#3 {main}
  thrown
---------------------------------------------------------------
[ 2017-08-27T14:15:47+08:00 ] 127.0.0.1 127.0.0.1 GET /index.php/v1/product
[ error ] [1]Uncaught exception 'think\exception\ErrorException' with message 'Argument 1 passed to app\lib\exception\ExceptionHandler::render() must be an instance of think\Exception, instance of think\exception\RouteNotFoundException given, called in C:\Users\cheyod\Desktop\Home\WWW\bigbase\thinkphp\library\think\Error.php on line 47 and defined' in C:\Users\cheyod\Desktop\Home\WWW\bigbase\application\lib\exception\ExceptionHandler.php:15
Stack trace:
#0 C:\Users\cheyod\Desktop\Home\WWW\bigbase\application\lib\exception\ExceptionHandler.php(15): think\Error::appError(4096, 'Argument 1 pass...', 'C:\\Users\\cheyod...', 15, Array)
#1 C:\Users\cheyod\Desktop\Home\WWW\bigbase\thinkphp\library\think\Error.php(47): app\lib\exception\ExceptionHandler->render(Object(think\exception\RouteNotFoundException))
#2 [internal function]: think\Error::appException(Object(think\exception\RouteNotFoundException))
#3 {main}
  thrown
[ error ] Uncaught exception 'think\exception\ErrorException' with message 'Argument 1 passed to app\lib\exception\ExceptionHandler::render() must be an instance of think\Exception, instance of think\exception\RouteNotFoundException given, called in C:\Users\cheyod\Desktop\Home\WWW\bigbase\thinkphp\library\think\Error.php on line 47 and defined' in C:\Users\cheyod\Desktop\Home\WWW\bigbase\application\lib\exception\ExceptionHandler.php:15
Stack trace:
#0 C:\Users\cheyod\Desktop\Home\WWW\bigbase\application\lib\exception\ExceptionHandler.php(15): think\Error::appError(4096, 'Argument 1 pass...', 'C:\\Users\\cheyod...', 15, Array)
#1 C:\Users\cheyod\Desktop\Home\WWW\bigbase\thinkphp\library\think\Error.php(47): app\lib\exception\ExceptionHandler->render(Object(think\exception\RouteNotFoundException))
#2 [internal function]: think\Error::appException(Object(think\exception\RouteNotFoundException))
#3 {main}
  thrown
---------------------------------------------------------------
[ 2017-08-27T14:15:47+08:00 ] 127.0.0.1 127.0.0.1 GET /index.php/v1/product
[ error ] [1]Uncaught exception 'think\exception\ErrorException' with message 'Argument 1 passed to app\lib\exception\ExceptionHandler::render() must be an instance of think\Exception, instance of think\exception\RouteNotFoundException given, called in C:\Users\cheyod\Desktop\Home\WWW\bigbase\thinkphp\library\think\Error.php on line 47 and defined' in C:\Users\cheyod\Desktop\Home\WWW\bigbase\application\lib\exception\ExceptionHandler.php:15
Stack trace:
#0 C:\Users\cheyod\Desktop\Home\WWW\bigbase\application\lib\exception\ExceptionHandler.php(15): think\Error::appError(4096, 'Argument 1 pass...', 'C:\\Users\\cheyod...', 15, Array)
#1 C:\Users\cheyod\Desktop\Home\WWW\bigbase\thinkphp\library\think\Error.php(47): app\lib\exception\ExceptionHandler->render(Object(think\exception\RouteNotFoundException))
#2 [internal function]: think\Error::appException(Object(think\exception\RouteNotFoundException))
#3 {main}
  thrown
[ error ] Uncaught exception 'think\exception\ErrorException' with message 'Argument 1 passed to app\lib\exception\ExceptionHandler::render() must be an instance of think\Exception, instance of think\exception\RouteNotFoundException given, called in C:\Users\cheyod\Desktop\Home\WWW\bigbase\thinkphp\library\think\Error.php on line 47 and defined' in C:\Users\cheyod\Desktop\Home\WWW\bigbase\application\lib\exception\ExceptionHandler.php:15
Stack trace:
#0 C:\Users\cheyod\Desktop\Home\WWW\bigbase\application\lib\exception\ExceptionHandler.php(15): think\Error::appError(4096, 'Argument 1 pass...', 'C:\\Users\\cheyod...', 15, Array)
#1 C:\Users\cheyod\Desktop\Home\WWW\bigbase\thinkphp\library\think\Error.php(47): app\lib\exception\ExceptionHandler->render(Object(think\exception\RouteNotFoundException))
#2 [internal function]: think\Error::appException(Object(think\exception\RouteNotFoundException))
#3 {main}
  thrown
---------------------------------------------------------------
[ 2017-08-27T14:15:59+08:00 ] 127.0.0.1 127.0.0.1 GET /index.php/v1/product
[ error ] [1]Uncaught exception 'think\exception\ErrorException' with message 'Argument 1 passed to app\lib\exception\ExceptionHandler::render() must be an instance of think\Exception, instance of think\exception\RouteNotFoundException given, called in C:\Users\cheyod\Desktop\Home\WWW\bigbase\thinkphp\library\think\Error.php on line 47 and defined' in C:\Users\cheyod\Desktop\Home\WWW\bigbase\application\lib\exception\ExceptionHandler.php:15
Stack trace:
#0 C:\Users\cheyod\Desktop\Home\WWW\bigbase\application\lib\exception\ExceptionHandler.php(15): think\Error::appError(4096, 'Argument 1 pass...', 'C:\\Users\\cheyod...', 15, Array)
#1 C:\Users\cheyod\Desktop\Home\WWW\bigbase\thinkphp\library\think\Error.php(47): app\lib\exception\ExceptionHandler->render(Object(think\exception\RouteNotFoundException))
#2 [internal function]: think\Error::appException(Object(think\exception\RouteNotFoundException))
#3 {main}
  thrown
[ error ] Uncaught exception 'think\exception\ErrorException' with message 'Argument 1 passed to app\lib\exception\ExceptionHandler::render() must be an instance of think\Exception, instance of think\exception\RouteNotFoundException given, called in C:\Users\cheyod\Desktop\Home\WWW\bigbase\thinkphp\library\think\Error.php on line 47 and defined' in C:\Users\cheyod\Desktop\Home\WWW\bigbase\application\lib\exception\ExceptionHandler.php:15
Stack trace:
#0 C:\Users\cheyod\Desktop\Home\WWW\bigbase\application\lib\exception\ExceptionHandler.php(15): think\Error::appError(4096, 'Argument 1 pass...', 'C:\\Users\\cheyod...', 15, Array)
#1 C:\Users\cheyod\Desktop\Home\WWW\bigbase\thinkphp\library\think\Error.php(47): app\lib\exception\ExceptionHandler->render(Object(think\exception\RouteNotFoundException))
#2 [internal function]: think\Error::appException(Object(think\exception\RouteNotFoundException))
#3 {main}
  thrown
---------------------------------------------------------------
[ 2017-08-27T14:16:00+08:00 ] 127.0.0.1 127.0.0.1 GET /index.php/v1/product
[ error ] [1]Uncaught exception 'think\exception\ErrorException' with message 'Argument 1 passed to app\lib\exception\ExceptionHandler::render() must be an instance of think\Exception, instance of think\exception\RouteNotFoundException given, called in C:\Users\cheyod\Desktop\Home\WWW\bigbase\thinkphp\library\think\Error.php on line 47 and defined' in C:\Users\cheyod\Desktop\Home\WWW\bigbase\application\lib\exception\ExceptionHandler.php:15
Stack trace:
#0 C:\Users\cheyod\Desktop\Home\WWW\bigbase\application\lib\exception\ExceptionHandler.php(15): think\Error::appError(4096, 'Argument 1 pass...', 'C:\\Users\\cheyod...', 15, Array)
#1 C:\Users\cheyod\Desktop\Home\WWW\bigbase\thinkphp\library\think\Error.php(47): app\lib\exception\ExceptionHandler->render(Object(think\exception\RouteNotFoundException))
#2 [internal function]: think\Error::appException(Object(think\exception\RouteNotFoundException))
#3 {main}
  thrown
[ error ] Uncaught exception 'think\exception\ErrorException' with message 'Argument 1 passed to app\lib\exception\ExceptionHandler::render() must be an instance of think\Exception, instance of think\exception\RouteNotFoundException given, called in C:\Users\cheyod\Desktop\Home\WWW\bigbase\thinkphp\library\think\Error.php on line 47 and defined' in C:\Users\cheyod\Desktop\Home\WWW\bigbase\application\lib\exception\ExceptionHandler.php:15
Stack trace:
#0 C:\Users\cheyod\Desktop\Home\WWW\bigbase\application\lib\exception\ExceptionHandler.php(15): think\Error::appError(4096, 'Argument 1 pass...', 'C:\\Users\\cheyod...', 15, Array)
#1 C:\Users\cheyod\Desktop\Home\WWW\bigbase\thinkphp\library\think\Error.php(47): app\lib\exception\ExceptionHandler->render(Object(think\exception\RouteNotFoundException))
#2 [internal function]: think\Error::appException(Object(think\exception\RouteNotFoundException))
#3 {main}
  thrown
---------------------------------------------------------------
[ 2017-08-27T14:16:00+08:00 ] 127.0.0.1 127.0.0.1 GET /index.php/v1/product
[ error ] [1]Uncaught exception 'think\exception\ErrorException' with message 'Argument 1 passed to app\lib\exception\ExceptionHandler::render() must be an instance of think\Exception, instance of think\exception\RouteNotFoundException given, called in C:\Users\cheyod\Desktop\Home\WWW\bigbase\thinkphp\library\think\Error.php on line 47 and defined' in C:\Users\cheyod\Desktop\Home\WWW\bigbase\application\lib\exception\ExceptionHandler.php:15
Stack trace:
#0 C:\Users\cheyod\Desktop\Home\WWW\bigbase\application\lib\exception\ExceptionHandler.php(15): think\Error::appError(4096, 'Argument 1 pass...', 'C:\\Users\\cheyod...', 15, Array)
#1 C:\Users\cheyod\Desktop\Home\WWW\bigbase\thinkphp\library\think\Error.php(47): app\lib\exception\ExceptionHandler->render(Object(think\exception\RouteNotFoundException))
#2 [internal function]: think\Error::appException(Object(think\exception\RouteNotFoundException))
#3 {main}
  thrown
[ error ] Uncaught exception 'think\exception\ErrorException' with message 'Argument 1 passed to app\lib\exception\ExceptionHandler::render() must be an instance of think\Exception, instance of think\exception\RouteNotFoundException given, called in C:\Users\cheyod\Desktop\Home\WWW\bigbase\thinkphp\library\think\Error.php on line 47 and defined' in C:\Users\cheyod\Desktop\Home\WWW\bigbase\application\lib\exception\ExceptionHandler.php:15
Stack trace:
#0 C:\Users\cheyod\Desktop\Home\WWW\bigbase\application\lib\exception\ExceptionHandler.php(15): think\Error::appError(4096, 'Argument 1 pass...', 'C:\\Users\\cheyod...', 15, Array)
#1 C:\Users\cheyod\Desktop\Home\WWW\bigbase\thinkphp\library\think\Error.php(47): app\lib\exception\ExceptionHandler->render(Object(think\exception\RouteNotFoundException))
#2 [internal function]: think\Error::appException(Object(think\exception\RouteNotFoundException))
#3 {main}
  thrown
---------------------------------------------------------------
[ 2017-08-27T14:16:18+08:00 ] 127.0.0.1 127.0.0.1 GET /index.php/v1/product
[ error ] [1]Uncaught exception 'think\exception\ErrorException' with message 'Argument 1 passed to app\lib\exception\ExceptionHandler::render() must be an instance of think\Exception, instance of think\exception\HttpException given, called in C:\Users\cheyod\Desktop\Home\WWW\bigbase\thinkphp\library\think\Error.php on line 47 and defined' in C:\Users\cheyod\Desktop\Home\WWW\bigbase\application\lib\exception\ExceptionHandler.php:15
Stack trace:
#0 C:\Users\cheyod\Desktop\Home\WWW\bigbase\application\lib\exception\ExceptionHandler.php(15): think\Error::appError(4096, 'Argument 1 pass...', 'C:\\Users\\cheyod...', 15, Array)
#1 C:\Users\cheyod\Desktop\Home\WWW\bigbase\thinkphp\library\think\Error.php(47): app\lib\exception\ExceptionHandler->render(Object(think\exception\HttpException))
#2 [internal function]: think\Error::appException(Object(think\exception\HttpException))
#3 {main}
  thrown
[ error ] Uncaught exception 'think\exception\ErrorException' with message 'Argument 1 passed to app\lib\exception\ExceptionHandler::render() must be an instance of think\Exception, instance of think\exception\HttpException given, called in C:\Users\cheyod\Desktop\Home\WWW\bigbase\thinkphp\library\think\Error.php on line 47 and defined' in C:\Users\cheyod\Desktop\Home\WWW\bigbase\application\lib\exception\ExceptionHandler.php:15
Stack trace:
#0 C:\Users\cheyod\Desktop\Home\WWW\bigbase\application\lib\exception\ExceptionHandler.php(15): think\Error::appError(4096, 'Argument 1 pass...', 'C:\\Users\\cheyod...', 15, Array)
#1 C:\Users\cheyod\Desktop\Home\WWW\bigbase\thinkphp\library\think\Error.php(47): app\lib\exception\ExceptionHandler->render(Object(think\exception\HttpException))
#2 [internal function]: think\Error::appException(Object(think\exception\HttpException))
#3 {main}
  thrown
---------------------------------------------------------------
[ 2017-08-27T14:16:18+08:00 ] 127.0.0.1 127.0.0.1 GET /index.php/v1/product
[ error ] [1]Uncaught exception 'think\exception\ErrorException' with message 'Argument 1 passed to app\lib\exception\ExceptionHandler::render() must be an instance of think\Exception, instance of think\exception\HttpException given, called in C:\Users\cheyod\Desktop\Home\WWW\bigbase\thinkphp\library\think\Error.php on line 47 and defined' in C:\Users\cheyod\Desktop\Home\WWW\bigbase\application\lib\exception\ExceptionHandler.php:15
Stack trace:
#0 C:\Users\cheyod\Desktop\Home\WWW\bigbase\application\lib\exception\ExceptionHandler.php(15): think\Error::appError(4096, 'Argument 1 pass...', 'C:\\Users\\cheyod...', 15, Array)
#1 C:\Users\cheyod\Desktop\Home\WWW\bigbase\thinkphp\library\think\Error.php(47): app\lib\exception\ExceptionHandler->render(Object(think\exception\HttpException))
#2 [internal function]: think\Error::appException(Object(think\exception\HttpException))
#3 {main}
  thrown
[ error ] Uncaught exception 'think\exception\ErrorException' with message 'Argument 1 passed to app\lib\exception\ExceptionHandler::render() must be an instance of think\Exception, instance of think\exception\HttpException given, called in C:\Users\cheyod\Desktop\Home\WWW\bigbase\thinkphp\library\think\Error.php on line 47 and defined' in C:\Users\cheyod\Desktop\Home\WWW\bigbase\application\lib\exception\ExceptionHandler.php:15
Stack trace:
#0 C:\Users\cheyod\Desktop\Home\WWW\bigbase\application\lib\exception\ExceptionHandler.php(15): think\Error::appError(4096, 'Argument 1 pass...', 'C:\\Users\\cheyod...', 15, Array)
#1 C:\Users\cheyod\Desktop\Home\WWW\bigbase\thinkphp\library\think\Error.php(47): app\lib\exception\ExceptionHandler->render(Object(think\exception\HttpException))
#2 [internal function]: think\Error::appException(Object(think\exception\HttpException))
#3 {main}
  thrown
---------------------------------------------------------------
[ 2017-08-27T14:16:18+08:00 ] 127.0.0.1 127.0.0.1 GET /index.php/v1/product
[ error ] [1]Uncaught exception 'think\exception\ErrorException' with message 'Argument 1 passed to app\lib\exception\ExceptionHandler::render() must be an instance of think\Exception, instance of think\exception\HttpException given, called in C:\Users\cheyod\Desktop\Home\WWW\bigbase\thinkphp\library\think\Error.php on line 47 and defined' in C:\Users\cheyod\Desktop\Home\WWW\bigbase\application\lib\exception\ExceptionHandler.php:15
Stack trace:
#0 C:\Users\cheyod\Desktop\Home\WWW\bigbase\application\lib\exception\ExceptionHandler.php(15): think\Error::appError(4096, 'Argument 1 pass...', 'C:\\Users\\cheyod...', 15, Array)
#1 C:\Users\cheyod\Desktop\Home\WWW\bigbase\thinkphp\library\think\Error.php(47): app\lib\exception\ExceptionHandler->render(Object(think\exception\HttpException))
#2 [internal function]: think\Error::appException(Object(think\exception\HttpException))
#3 {main}
  thrown
[ error ] Uncaught exception 'think\exception\ErrorException' with message 'Argument 1 passed to app\lib\exception\ExceptionHandler::render() must be an instance of think\Exception, instance of think\exception\HttpException given, called in C:\Users\cheyod\Desktop\Home\WWW\bigbase\thinkphp\library\think\Error.php on line 47 and defined' in C:\Users\cheyod\Desktop\Home\WWW\bigbase\application\lib\exception\ExceptionHandler.php:15
Stack trace:
#0 C:\Users\cheyod\Desktop\Home\WWW\bigbase\application\lib\exception\ExceptionHandler.php(15): think\Error::appError(4096, 'Argument 1 pass...', 'C:\\Users\\cheyod...', 15, Array)
#1 C:\Users\cheyod\Desktop\Home\WWW\bigbase\thinkphp\library\think\Error.php(47): app\lib\exception\ExceptionHandler->render(Object(think\exception\HttpException))
#2 [internal function]: think\Error::appException(Object(think\exception\HttpException))
#3 {main}
  thrown
---------------------------------------------------------------
[ 2017-08-27T14:16:35+08:00 ] 127.0.0.1 127.0.0.1 GET /index.php/v1/product
[ error ] [1]Uncaught exception 'think\exception\ErrorException' with message 'Argument 1 passed to app\lib\exception\ExceptionHandler::render() must be an instance of think\Exception, instance of think\exception\HttpException given, called in C:\Users\cheyod\Desktop\Home\WWW\bigbase\thinkphp\library\think\Error.php on line 47 and defined' in C:\Users\cheyod\Desktop\Home\WWW\bigbase\application\lib\exception\ExceptionHandler.php:15
Stack trace:
#0 C:\Users\cheyod\Desktop\Home\WWW\bigbase\application\lib\exception\ExceptionHandler.php(15): think\Error::appError(4096, 'Argument 1 pass...', 'C:\\Users\\cheyod...', 15, Array)
#1 C:\Users\cheyod\Desktop\Home\WWW\bigbase\thinkphp\library\think\Error.php(47): app\lib\exception\ExceptionHandler->render(Object(think\exception\HttpException))
#2 [internal function]: think\Error::appException(Object(think\exception\HttpException))
#3 {main}
  thrown
[ error ] Uncaught exception 'think\exception\ErrorException' with message 'Argument 1 passed to app\lib\exception\ExceptionHandler::render() must be an instance of think\Exception, instance of think\exception\HttpException given, called in C:\Users\cheyod\Desktop\Home\WWW\bigbase\thinkphp\library\think\Error.php on line 47 and defined' in C:\Users\cheyod\Desktop\Home\WWW\bigbase\application\lib\exception\ExceptionHandler.php:15
Stack trace:
#0 C:\Users\cheyod\Desktop\Home\WWW\bigbase\application\lib\exception\ExceptionHandler.php(15): think\Error::appError(4096, 'Argument 1 pass...', 'C:\\Users\\cheyod...', 15, Array)
#1 C:\Users\cheyod\Desktop\Home\WWW\bigbase\thinkphp\library\think\Error.php(47): app\lib\exception\ExceptionHandler->render(Object(think\exception\HttpException))
#2 [internal function]: think\Error::appException(Object(think\exception\HttpException))
#3 {main}
  thrown
---------------------------------------------------------------
[ 2017-08-27T14:16:35+08:00 ] 127.0.0.1 127.0.0.1 GET /index.php/v1/product
[ error ] [1]Uncaught exception 'think\exception\ErrorException' with message 'Argument 1 passed to app\lib\exception\ExceptionHandler::render() must be an instance of think\Exception, instance of think\exception\HttpException given, called in C:\Users\cheyod\Desktop\Home\WWW\bigbase\thinkphp\library\think\Error.php on line 47 and defined' in C:\Users\cheyod\Desktop\Home\WWW\bigbase\application\lib\exception\ExceptionHandler.php:15
Stack trace:
#0 C:\Users\cheyod\Desktop\Home\WWW\bigbase\application\lib\exception\ExceptionHandler.php(15): think\Error::appError(4096, 'Argument 1 pass...', 'C:\\Users\\cheyod...', 15, Array)
#1 C:\Users\cheyod\Desktop\Home\WWW\bigbase\thinkphp\library\think\Error.php(47): app\lib\exception\ExceptionHandler->render(Object(think\exception\HttpException))
#2 [internal function]: think\Error::appException(Object(think\exception\HttpException))
#3 {main}
  thrown
[ error ] Uncaught exception 'think\exception\ErrorException' with message 'Argument 1 passed to app\lib\exception\ExceptionHandler::render() must be an instance of think\Exception, instance of think\exception\HttpException given, called in C:\Users\cheyod\Desktop\Home\WWW\bigbase\thinkphp\library\think\Error.php on line 47 and defined' in C:\Users\cheyod\Desktop\Home\WWW\bigbase\application\lib\exception\ExceptionHandler.php:15
Stack trace:
#0 C:\Users\cheyod\Desktop\Home\WWW\bigbase\application\lib\exception\ExceptionHandler.php(15): think\Error::appError(4096, 'Argument 1 pass...', 'C:\\Users\\cheyod...', 15, Array)
#1 C:\Users\cheyod\Desktop\Home\WWW\bigbase\thinkphp\library\think\Error.php(47): app\lib\exception\ExceptionHandler->render(Object(think\exception\HttpException))
#2 [internal function]: think\Error::appException(Object(think\exception\HttpException))
#3 {main}
  thrown
---------------------------------------------------------------
[ 2017-08-27T14:16:36+08:00 ] 127.0.0.1 127.0.0.1 GET /index.php/v1/product
[ error ] [1]Uncaught exception 'think\exception\ErrorException' with message 'Argument 1 passed to app\lib\exception\ExceptionHandler::render() must be an instance of think\Exception, instance of think\exception\HttpException given, called in C:\Users\cheyod\Desktop\Home\WWW\bigbase\thinkphp\library\think\Error.php on line 47 and defined' in C:\Users\cheyod\Desktop\Home\WWW\bigbase\application\lib\exception\ExceptionHandler.php:15
Stack trace:
#0 C:\Users\cheyod\Desktop\Home\WWW\bigbase\application\lib\exception\ExceptionHandler.php(15): think\Error::appError(4096, 'Argument 1 pass...', 'C:\\Users\\cheyod...', 15, Array)
#1 C:\Users\cheyod\Desktop\Home\WWW\bigbase\thinkphp\library\think\Error.php(47): app\lib\exception\ExceptionHandler->render(Object(think\exception\HttpException))
#2 [internal function]: think\Error::appException(Object(think\exception\HttpException))
#3 {main}
  thrown
[ error ] Uncaught exception 'think\exception\ErrorException' with message 'Argument 1 passed to app\lib\exception\ExceptionHandler::render() must be an instance of think\Exception, instance of think\exception\HttpException given, called in C:\Users\cheyod\Desktop\Home\WWW\bigbase\thinkphp\library\think\Error.php on line 47 and defined' in C:\Users\cheyod\Desktop\Home\WWW\bigbase\application\lib\exception\ExceptionHandler.php:15
Stack trace:
#0 C:\Users\cheyod\Desktop\Home\WWW\bigbase\application\lib\exception\ExceptionHandler.php(15): think\Error::appError(4096, 'Argument 1 pass...', 'C:\\Users\\cheyod...', 15, Array)
#1 C:\Users\cheyod\Desktop\Home\WWW\bigbase\thinkphp\library\think\Error.php(47): app\lib\exception\ExceptionHandler->render(Object(think\exception\HttpException))
#2 [internal function]: think\Error::appException(Object(think\exception\HttpException))
#3 {main}
  thrown
---------------------------------------------------------------
[ 2017-08-27T14:16:38+08:00 ] 127.0.0.1 127.0.0.1 GET /index.php/v1/product
[ error ] [1]Uncaught exception 'think\exception\ErrorException' with message 'Argument 1 passed to app\lib\exception\ExceptionHandler::render() must be an instance of think\Exception, instance of think\exception\HttpException given, called in C:\Users\cheyod\Desktop\Home\WWW\bigbase\thinkphp\library\think\Error.php on line 47 and defined' in C:\Users\cheyod\Desktop\Home\WWW\bigbase\application\lib\exception\ExceptionHandler.php:15
Stack trace:
#0 C:\Users\cheyod\Desktop\Home\WWW\bigbase\application\lib\exception\ExceptionHandler.php(15): think\Error::appError(4096, 'Argument 1 pass...', 'C:\\Users\\cheyod...', 15, Array)
#1 C:\Users\cheyod\Desktop\Home\WWW\bigbase\thinkphp\library\think\Error.php(47): app\lib\exception\ExceptionHandler->render(Object(think\exception\HttpException))
#2 [internal function]: think\Error::appException(Object(think\exception\HttpException))
#3 {main}
  thrown
[ error ] Uncaught exception 'think\exception\ErrorException' with message 'Argument 1 passed to app\lib\exception\ExceptionHandler::render() must be an instance of think\Exception, instance of think\exception\HttpException given, called in C:\Users\cheyod\Desktop\Home\WWW\bigbase\thinkphp\library\think\Error.php on line 47 and defined' in C:\Users\cheyod\Desktop\Home\WWW\bigbase\application\lib\exception\ExceptionHandler.php:15
Stack trace:
#0 C:\Users\cheyod\Desktop\Home\WWW\bigbase\application\lib\exception\ExceptionHandler.php(15): think\Error::appError(4096, 'Argument 1 pass...', 'C:\\Users\\cheyod...', 15, Array)
#1 C:\Users\cheyod\Desktop\Home\WWW\bigbase\thinkphp\library\think\Error.php(47): app\lib\exception\ExceptionHandler->render(Object(think\exception\HttpException))
#2 [internal function]: think\Error::appException(Object(think\exception\HttpException))
#3 {main}
  thrown
---------------------------------------------------------------
[ 2017-08-27T14:16:56+08:00 ] 127.0.0.1 127.0.0.1 GET /index.php/v1/selProduct
[ error ] [1]Uncaught exception 'think\exception\ErrorException' with message 'Argument 1 passed to app\lib\exception\ExceptionHandler::render() must be an instance of think\Exception, instance of think\exception\HttpException given, called in C:\Users\cheyod\Desktop\Home\WWW\bigbase\thinkphp\library\think\Error.php on line 47 and defined' in C:\Users\cheyod\Desktop\Home\WWW\bigbase\application\lib\exception\ExceptionHandler.php:15
Stack trace:
#0 C:\Users\cheyod\Desktop\Home\WWW\bigbase\application\lib\exception\ExceptionHandler.php(15): think\Error::appError(4096, 'Argument 1 pass...', 'C:\\Users\\cheyod...', 15, Array)
#1 C:\Users\cheyod\Desktop\Home\WWW\bigbase\thinkphp\library\think\Error.php(47): app\lib\exception\ExceptionHandler->render(Object(think\exception\HttpException))
#2 [internal function]: think\Error::appException(Object(think\exception\HttpException))
#3 {main}
  thrown
[ error ] Uncaught exception 'think\exception\ErrorException' with message 'Argument 1 passed to app\lib\exception\ExceptionHandler::render() must be an instance of think\Exception, instance of think\exception\HttpException given, called in C:\Users\cheyod\Desktop\Home\WWW\bigbase\thinkphp\library\think\Error.php on line 47 and defined' in C:\Users\cheyod\Desktop\Home\WWW\bigbase\application\lib\exception\ExceptionHandler.php:15
Stack trace:
#0 C:\Users\cheyod\Desktop\Home\WWW\bigbase\application\lib\exception\ExceptionHandler.php(15): think\Error::appError(4096, 'Argument 1 pass...', 'C:\\Users\\cheyod...', 15, Array)
#1 C:\Users\cheyod\Desktop\Home\WWW\bigbase\thinkphp\library\think\Error.php(47): app\lib\exception\ExceptionHandler->render(Object(think\exception\HttpException))
#2 [internal function]: think\Error::appException(Object(think\exception\HttpException))
#3 {main}
  thrown
---------------------------------------------------------------
[ 2017-08-27T14:17:52+08:00 ] 127.0.0.1 127.0.0.1 GET /index.php/v1.Product.Product.Product.Product.Product.Product.Product.Product.Product.Product.Product.Product.Product.Product.Product.Product.Product.Product.Product.Product/selProduct.html
[ error ] [1]Uncaught exception 'think\exception\ErrorException' with message 'Argument 1 passed to app\lib\exception\ExceptionHandler::render() must be an instance of think\Exception, instance of think\exception\HttpException given, called in C:\Users\cheyod\Desktop\Home\WWW\bigbase\thinkphp\library\think\Error.php on line 47 and defined' in C:\Users\cheyod\Desktop\Home\WWW\bigbase\application\lib\exception\ExceptionHandler.php:15
Stack trace:
#0 C:\Users\cheyod\Desktop\Home\WWW\bigbase\application\lib\exception\ExceptionHandler.php(15): think\Error::appError(4096, 'Argument 1 pass...', 'C:\\Users\\cheyod...', 15, Array)
#1 C:\Users\cheyod\Desktop\Home\WWW\bigbase\thinkphp\library\think\Error.php(47): app\lib\exception\ExceptionHandler->render(Object(think\exception\HttpException))
#2 [internal function]: think\Error::appException(Object(think\exception\HttpException))
#3 {main}
  thrown
[ error ] Uncaught exception 'think\exception\ErrorException' with message 'Argument 1 passed to app\lib\exception\ExceptionHandler::render() must be an instance of think\Exception, instance of think\exception\HttpException given, called in C:\Users\cheyod\Desktop\Home\WWW\bigbase\thinkphp\library\think\Error.php on line 47 and defined' in C:\Users\cheyod\Desktop\Home\WWW\bigbase\application\lib\exception\ExceptionHandler.php:15
Stack trace:
#0 C:\Users\cheyod\Desktop\Home\WWW\bigbase\application\lib\exception\ExceptionHandler.php(15): think\Error::appError(4096, 'Argument 1 pass...', 'C:\\Users\\cheyod...', 15, Array)
#1 C:\Users\cheyod\Desktop\Home\WWW\bigbase\thinkphp\library\think\Error.php(47): app\lib\exception\ExceptionHandler->render(Object(think\exception\HttpException))
#2 [internal function]: think\Error::appException(Object(think\exception\HttpException))
#3 {main}
  thrown
---------------------------------------------------------------
[ 2017-08-27T14:18:03+08:00 ] 127.0.0.1 127.0.0.1 GET /index.php/v1/product
[ error ] [1]Uncaught exception 'think\exception\ErrorException' with message 'Argument 1 passed to app\lib\exception\ExceptionHandler::render() must be an instance of think\Exception, instance of think\exception\RouteNotFoundException given, called in C:\Users\cheyod\Desktop\Home\WWW\bigbase\thinkphp\library\think\Error.php on line 47 and defined' in C:\Users\cheyod\Desktop\Home\WWW\bigbase\application\lib\exception\ExceptionHandler.php:15
Stack trace:
#0 C:\Users\cheyod\Desktop\Home\WWW\bigbase\application\lib\exception\ExceptionHandler.php(15): think\Error::appError(4096, 'Argument 1 pass...', 'C:\\Users\\cheyod...', 15, Array)
#1 C:\Users\cheyod\Desktop\Home\WWW\bigbase\thinkphp\library\think\Error.php(47): app\lib\exception\ExceptionHandler->render(Object(think\exception\RouteNotFoundException))
#2 [internal function]: think\Error::appException(Object(think\exception\RouteNotFoundException))
#3 {main}
  thrown
[ error ] Uncaught exception 'think\exception\ErrorException' with message 'Argument 1 passed to app\lib\exception\ExceptionHandler::render() must be an instance of think\Exception, instance of think\exception\RouteNotFoundException given, called in C:\Users\cheyod\Desktop\Home\WWW\bigbase\thinkphp\library\think\Error.php on line 47 and defined' in C:\Users\cheyod\Desktop\Home\WWW\bigbase\application\lib\exception\ExceptionHandler.php:15
Stack trace:
#0 C:\Users\cheyod\Desktop\Home\WWW\bigbase\application\lib\exception\ExceptionHandler.php(15): think\Error::appError(4096, 'Argument 1 pass...', 'C:\\Users\\cheyod...', 15, Array)
#1 C:\Users\cheyod\Desktop\Home\WWW\bigbase\thinkphp\library\think\Error.php(47): app\lib\exception\ExceptionHandler->render(Object(think\exception\RouteNotFoundException))
#2 [internal function]: think\Error::appException(Object(think\exception\RouteNotFoundException))
#3 {main}
  thrown
---------------------------------------------------------------
[ 2017-08-27T14:18:12+08:00 ] 127.0.0.1 127.0.0.1 GET /index.php//v1/product
[ error ] [1]Uncaught exception 'think\exception\ErrorException' with message 'Argument 1 passed to app\lib\exception\ExceptionHandler::render() must be an instance of think\Exception, instance of think\exception\RouteNotFoundException given, called in C:\Users\cheyod\Desktop\Home\WWW\bigbase\thinkphp\library\think\Error.php on line 47 and defined' in C:\Users\cheyod\Desktop\Home\WWW\bigbase\application\lib\exception\ExceptionHandler.php:15
Stack trace:
#0 C:\Users\cheyod\Desktop\Home\WWW\bigbase\application\lib\exception\ExceptionHandler.php(15): think\Error::appError(4096, 'Argument 1 pass...', 'C:\\Users\\cheyod...', 15, Array)
#1 C:\Users\cheyod\Desktop\Home\WWW\bigbase\thinkphp\library\think\Error.php(47): app\lib\exception\ExceptionHandler->render(Object(think\exception\RouteNotFoundException))
#2 [internal function]: think\Error::appException(Object(think\exception\RouteNotFoundException))
#3 {main}
  thrown
[ error ] Uncaught exception 'think\exception\ErrorException' with message 'Argument 1 passed to app\lib\exception\ExceptionHandler::render() must be an instance of think\Exception, instance of think\exception\RouteNotFoundException given, called in C:\Users\cheyod\Desktop\Home\WWW\bigbase\thinkphp\library\think\Error.php on line 47 and defined' in C:\Users\cheyod\Desktop\Home\WWW\bigbase\application\lib\exception\ExceptionHandler.php:15
Stack trace:
#0 C:\Users\cheyod\Desktop\Home\WWW\bigbase\application\lib\exception\ExceptionHandler.php(15): think\Error::appError(4096, 'Argument 1 pass...', 'C:\\Users\\cheyod...', 15, Array)
#1 C:\Users\cheyod\Desktop\Home\WWW\bigbase\thinkphp\library\think\Error.php(47): app\lib\exception\ExceptionHandler->render(Object(think\exception\RouteNotFoundException))
#2 [internal function]: think\Error::appException(Object(think\exception\RouteNotFoundException))
#3 {main}
  thrown
---------------------------------------------------------------
[ 2017-08-27T14:18:16+08:00 ] 127.0.0.1 127.0.0.1 GET /index.php/v1/product
[ error ] [1]Uncaught exception 'think\exception\ErrorException' with message 'Argument 1 passed to app\lib\exception\ExceptionHandler::render() must be an instance of think\Exception, instance of think\exception\RouteNotFoundException given, called in C:\Users\cheyod\Desktop\Home\WWW\bigbase\thinkphp\library\think\Error.php on line 47 and defined' in C:\Users\cheyod\Desktop\Home\WWW\bigbase\application\lib\exception\ExceptionHandler.php:15
Stack trace:
#0 C:\Users\cheyod\Desktop\Home\WWW\bigbase\application\lib\exception\ExceptionHandler.php(15): think\Error::appError(4096, 'Argument 1 pass...', 'C:\\Users\\cheyod...', 15, Array)
#1 C:\Users\cheyod\Desktop\Home\WWW\bigbase\thinkphp\library\think\Error.php(47): app\lib\exception\ExceptionHandler->render(Object(think\exception\RouteNotFoundException))
#2 [internal function]: think\Error::appException(Object(think\exception\RouteNotFoundException))
#3 {main}
  thrown
[ error ] Uncaught exception 'think\exception\ErrorException' with message 'Argument 1 passed to app\lib\exception\ExceptionHandler::render() must be an instance of think\Exception, instance of think\exception\RouteNotFoundException given, called in C:\Users\cheyod\Desktop\Home\WWW\bigbase\thinkphp\library\think\Error.php on line 47 and defined' in C:\Users\cheyod\Desktop\Home\WWW\bigbase\application\lib\exception\ExceptionHandler.php:15
Stack trace:
#0 C:\Users\cheyod\Desktop\Home\WWW\bigbase\application\lib\exception\ExceptionHandler.php(15): think\Error::appError(4096, 'Argument 1 pass...', 'C:\\Users\\cheyod...', 15, Array)
#1 C:\Users\cheyod\Desktop\Home\WWW\bigbase\thinkphp\library\think\Error.php(47): app\lib\exception\ExceptionHandler->render(Object(think\exception\RouteNotFoundException))
#2 [internal function]: think\Error::appException(Object(think\exception\RouteNotFoundException))
#3 {main}
  thrown
---------------------------------------------------------------
[ 2017-08-27T14:21:26+08:00 ] 127.0.0.1 127.0.0.1 GET /index.php/v1/product
[ error ] [1]Uncaught exception 'think\exception\ErrorException' with message 'Argument 1 passed to app\lib\exception\ExceptionHandler::render() must be an instance of think\Exception, instance of think\exception\RouteNotFoundException given, called in C:\Users\cheyod\Desktop\Home\WWW\bigbase\thinkphp\library\think\Error.php on line 47 and defined' in C:\Users\cheyod\Desktop\Home\WWW\bigbase\application\lib\exception\ExceptionHandler.php:15
Stack trace:
#0 C:\Users\cheyod\Desktop\Home\WWW\bigbase\application\lib\exception\ExceptionHandler.php(15): think\Error::appError(4096, 'Argument 1 pass...', 'C:\\Users\\cheyod...', 15, Array)
#1 C:\Users\cheyod\Desktop\Home\WWW\bigbase\thinkphp\library\think\Error.php(47): app\lib\exception\ExceptionHandler->render(Object(think\exception\RouteNotFoundException))
#2 [internal function]: think\Error::appException(Object(think\exception\RouteNotFoundException))
#3 {main}
  thrown
[ error ] Uncaught exception 'think\exception\ErrorException' with message 'Argument 1 passed to app\lib\exception\ExceptionHandler::render() must be an instance of think\Exception, instance of think\exception\RouteNotFoundException given, called in C:\Users\cheyod\Desktop\Home\WWW\bigbase\thinkphp\library\think\Error.php on line 47 and defined' in C:\Users\cheyod\Desktop\Home\WWW\bigbase\application\lib\exception\ExceptionHandler.php:15
Stack trace:
#0 C:\Users\cheyod\Desktop\Home\WWW\bigbase\application\lib\exception\ExceptionHandler.php(15): think\Error::appError(4096, 'Argument 1 pass...', 'C:\\Users\\cheyod...', 15, Array)
#1 C:\Users\cheyod\Desktop\Home\WWW\bigbase\thinkphp\library\think\Error.php(47): app\lib\exception\ExceptionHandler->render(Object(think\exception\RouteNotFoundException))
#2 [internal function]: think\Error::appException(Object(think\exception\RouteNotFoundException))
#3 {main}
  thrown
---------------------------------------------------------------
[ 2017-08-27T14:21:27+08:00 ] 127.0.0.1 127.0.0.1 GET /index.php/v1/product
[ error ] [1]Uncaught exception 'think\exception\ErrorException' with message 'Argument 1 passed to app\lib\exception\ExceptionHandler::render() must be an instance of think\Exception, instance of think\exception\RouteNotFoundException given, called in C:\Users\cheyod\Desktop\Home\WWW\bigbase\thinkphp\library\think\Error.php on line 47 and defined' in C:\Users\cheyod\Desktop\Home\WWW\bigbase\application\lib\exception\ExceptionHandler.php:15
Stack trace:
#0 C:\Users\cheyod\Desktop\Home\WWW\bigbase\application\lib\exception\ExceptionHandler.php(15): think\Error::appError(4096, 'Argument 1 pass...', 'C:\\Users\\cheyod...', 15, Array)
#1 C:\Users\cheyod\Desktop\Home\WWW\bigbase\thinkphp\library\think\Error.php(47): app\lib\exception\ExceptionHandler->render(Object(think\exception\RouteNotFoundException))
#2 [internal function]: think\Error::appException(Object(think\exception\RouteNotFoundException))
#3 {main}
  thrown
[ error ] Uncaught exception 'think\exception\ErrorException' with message 'Argument 1 passed to app\lib\exception\ExceptionHandler::render() must be an instance of think\Exception, instance of think\exception\RouteNotFoundException given, called in C:\Users\cheyod\Desktop\Home\WWW\bigbase\thinkphp\library\think\Error.php on line 47 and defined' in C:\Users\cheyod\Desktop\Home\WWW\bigbase\application\lib\exception\ExceptionHandler.php:15
Stack trace:
#0 C:\Users\cheyod\Desktop\Home\WWW\bigbase\application\lib\exception\ExceptionHandler.php(15): think\Error::appError(4096, 'Argument 1 pass...', 'C:\\Users\\cheyod...', 15, Array)
#1 C:\Users\cheyod\Desktop\Home\WWW\bigbase\thinkphp\library\think\Error.php(47): app\lib\exception\ExceptionHandler->render(Object(think\exception\RouteNotFoundException))
#2 [internal function]: think\Error::appException(Object(think\exception\RouteNotFoundException))
#3 {main}
  thrown
---------------------------------------------------------------
[ 2017-08-27T14:21:27+08:00 ] 127.0.0.1 127.0.0.1 GET /index.php/v1/product
[ error ] [1]Uncaught exception 'think\exception\ErrorException' with message 'Argument 1 passed to app\lib\exception\ExceptionHandler::render() must be an instance of think\Exception, instance of think\exception\RouteNotFoundException given, called in C:\Users\cheyod\Desktop\Home\WWW\bigbase\thinkphp\library\think\Error.php on line 47 and defined' in C:\Users\cheyod\Desktop\Home\WWW\bigbase\application\lib\exception\ExceptionHandler.php:15
Stack trace:
#0 C:\Users\cheyod\Desktop\Home\WWW\bigbase\application\lib\exception\ExceptionHandler.php(15): think\Error::appError(4096, 'Argument 1 pass...', 'C:\\Users\\cheyod...', 15, Array)
#1 C:\Users\cheyod\Desktop\Home\WWW\bigbase\thinkphp\library\think\Error.php(47): app\lib\exception\ExceptionHandler->render(Object(think\exception\RouteNotFoundException))
#2 [internal function]: think\Error::appException(Object(think\exception\RouteNotFoundException))
#3 {main}
  thrown
[ error ] Uncaught exception 'think\exception\ErrorException' with message 'Argument 1 passed to app\lib\exception\ExceptionHandler::render() must be an instance of think\Exception, instance of think\exception\RouteNotFoundException given, called in C:\Users\cheyod\Desktop\Home\WWW\bigbase\thinkphp\library\think\Error.php on line 47 and defined' in C:\Users\cheyod\Desktop\Home\WWW\bigbase\application\lib\exception\ExceptionHandler.php:15
Stack trace:
#0 C:\Users\cheyod\Desktop\Home\WWW\bigbase\application\lib\exception\ExceptionHandler.php(15): think\Error::appError(4096, 'Argument 1 pass...', 'C:\\Users\\cheyod...', 15, Array)
#1 C:\Users\cheyod\Desktop\Home\WWW\bigbase\thinkphp\library\think\Error.php(47): app\lib\exception\ExceptionHandler->render(Object(think\exception\RouteNotFoundException))
#2 [internal function]: think\Error::appException(Object(think\exception\RouteNotFoundException))
#3 {main}
  thrown
---------------------------------------------------------------
[ 2017-08-27T14:21:28+08:00 ] 127.0.0.1 127.0.0.1 GET /index.php/v1/product
[ error ] [1]Uncaught exception 'think\exception\ErrorException' with message 'Argument 1 passed to app\lib\exception\ExceptionHandler::render() must be an instance of think\Exception, instance of think\exception\RouteNotFoundException given, called in C:\Users\cheyod\Desktop\Home\WWW\bigbase\thinkphp\library\think\Error.php on line 47 and defined' in C:\Users\cheyod\Desktop\Home\WWW\bigbase\application\lib\exception\ExceptionHandler.php:15
Stack trace:
#0 C:\Users\cheyod\Desktop\Home\WWW\bigbase\application\lib\exception\ExceptionHandler.php(15): think\Error::appError(4096, 'Argument 1 pass...', 'C:\\Users\\cheyod...', 15, Array)
#1 C:\Users\cheyod\Desktop\Home\WWW\bigbase\thinkphp\library\think\Error.php(47): app\lib\exception\ExceptionHandler->render(Object(think\exception\RouteNotFoundException))
#2 [internal function]: think\Error::appException(Object(think\exception\RouteNotFoundException))
#3 {main}
  thrown
[ error ] Uncaught exception 'think\exception\ErrorException' with message 'Argument 1 passed to app\lib\exception\ExceptionHandler::render() must be an instance of think\Exception, instance of think\exception\RouteNotFoundException given, called in C:\Users\cheyod\Desktop\Home\WWW\bigbase\thinkphp\library\think\Error.php on line 47 and defined' in C:\Users\cheyod\Desktop\Home\WWW\bigbase\application\lib\exception\ExceptionHandler.php:15
Stack trace:
#0 C:\Users\cheyod\Desktop\Home\WWW\bigbase\application\lib\exception\ExceptionHandler.php(15): think\Error::appError(4096, 'Argument 1 pass...', 'C:\\Users\\cheyod...', 15, Array)
#1 C:\Users\cheyod\Desktop\Home\WWW\bigbase\thinkphp\library\think\Error.php(47): app\lib\exception\ExceptionHandler->render(Object(think\exception\RouteNotFoundException))
#2 [internal function]: think\Error::appException(Object(think\exception\RouteNotFoundException))
#3 {main}
  thrown
---------------------------------------------------------------
[ 2017-08-27T14:21:28+08:00 ] 127.0.0.1 127.0.0.1 GET /index.php/v1/product
[ error ] [1]Uncaught exception 'think\exception\ErrorException' with message 'Argument 1 passed to app\lib\exception\ExceptionHandler::render() must be an instance of think\Exception, instance of think\exception\RouteNotFoundException given, called in C:\Users\cheyod\Desktop\Home\WWW\bigbase\thinkphp\library\think\Error.php on line 47 and defined' in C:\Users\cheyod\Desktop\Home\WWW\bigbase\application\lib\exception\ExceptionHandler.php:15
Stack trace:
#0 C:\Users\cheyod\Desktop\Home\WWW\bigbase\application\lib\exception\ExceptionHandler.php(15): think\Error::appError(4096, 'Argument 1 pass...', 'C:\\Users\\cheyod...', 15, Array)
#1 C:\Users\cheyod\Desktop\Home\WWW\bigbase\thinkphp\library\think\Error.php(47): app\lib\exception\ExceptionHandler->render(Object(think\exception\RouteNotFoundException))
#2 [internal function]: think\Error::appException(Object(think\exception\RouteNotFoundException))
#3 {main}
  thrown
[ error ] Uncaught exception 'think\exception\ErrorException' with message 'Argument 1 passed to app\lib\exception\ExceptionHandler::render() must be an instance of think\Exception, instance of think\exception\RouteNotFoundException given, called in C:\Users\cheyod\Desktop\Home\WWW\bigbase\thinkphp\library\think\Error.php on line 47 and defined' in C:\Users\cheyod\Desktop\Home\WWW\bigbase\application\lib\exception\ExceptionHandler.php:15
Stack trace:
#0 C:\Users\cheyod\Desktop\Home\WWW\bigbase\application\lib\exception\ExceptionHandler.php(15): think\Error::appError(4096, 'Argument 1 pass...', 'C:\\Users\\cheyod...', 15, Array)
#1 C:\Users\cheyod\Desktop\Home\WWW\bigbase\thinkphp\library\think\Error.php(47): app\lib\exception\ExceptionHandler->render(Object(think\exception\RouteNotFoundException))
#2 [internal function]: think\Error::appException(Object(think\exception\RouteNotFoundException))
#3 {main}
  thrown
---------------------------------------------------------------
[ 2017-08-27T14:21:28+08:00 ] 127.0.0.1 127.0.0.1 GET /index.php/v1/product
[ error ] [1]Uncaught exception 'think\exception\ErrorException' with message 'Argument 1 passed to app\lib\exception\ExceptionHandler::render() must be an instance of think\Exception, instance of think\exception\RouteNotFoundException given, called in C:\Users\cheyod\Desktop\Home\WWW\bigbase\thinkphp\library\think\Error.php on line 47 and defined' in C:\Users\cheyod\Desktop\Home\WWW\bigbase\application\lib\exception\ExceptionHandler.php:15
Stack trace:
#0 C:\Users\cheyod\Desktop\Home\WWW\bigbase\application\lib\exception\ExceptionHandler.php(15): think\Error::appError(4096, 'Argument 1 pass...', 'C:\\Users\\cheyod...', 15, Array)
#1 C:\Users\cheyod\Desktop\Home\WWW\bigbase\thinkphp\library\think\Error.php(47): app\lib\exception\ExceptionHandler->render(Object(think\exception\RouteNotFoundException))
#2 [internal function]: think\Error::appException(Object(think\exception\RouteNotFoundException))
#3 {main}
  thrown
[ error ] Uncaught exception 'think\exception\ErrorException' with message 'Argument 1 passed to app\lib\exception\ExceptionHandler::render() must be an instance of think\Exception, instance of think\exception\RouteNotFoundException given, called in C:\Users\cheyod\Desktop\Home\WWW\bigbase\thinkphp\library\think\Error.php on line 47 and defined' in C:\Users\cheyod\Desktop\Home\WWW\bigbase\application\lib\exception\ExceptionHandler.php:15
Stack trace:
#0 C:\Users\cheyod\Desktop\Home\WWW\bigbase\application\lib\exception\ExceptionHandler.php(15): think\Error::appError(4096, 'Argument 1 pass...', 'C:\\Users\\cheyod...', 15, Array)
#1 C:\Users\cheyod\Desktop\Home\WWW\bigbase\thinkphp\library\think\Error.php(47): app\lib\exception\ExceptionHandler->render(Object(think\exception\RouteNotFoundException))
#2 [internal function]: think\Error::appException(Object(think\exception\RouteNotFoundException))
#3 {main}
  thrown
---------------------------------------------------------------
[ 2017-08-27T14:21:31+08:00 ] 127.0.0.1 127.0.0.1 GET /index.php/v1/productasdf
[ error ] [1]Uncaught exception 'think\exception\ErrorException' with message 'Argument 1 passed to app\lib\exception\ExceptionHandler::render() must be an instance of think\Exception, instance of think\exception\RouteNotFoundException given, called in C:\Users\cheyod\Desktop\Home\WWW\bigbase\thinkphp\library\think\Error.php on line 47 and defined' in C:\Users\cheyod\Desktop\Home\WWW\bigbase\application\lib\exception\ExceptionHandler.php:15
Stack trace:
#0 C:\Users\cheyod\Desktop\Home\WWW\bigbase\application\lib\exception\ExceptionHandler.php(15): think\Error::appError(4096, 'Argument 1 pass...', 'C:\\Users\\cheyod...', 15, Array)
#1 C:\Users\cheyod\Desktop\Home\WWW\bigbase\thinkphp\library\think\Error.php(47): app\lib\exception\ExceptionHandler->render(Object(think\exception\RouteNotFoundException))
#2 [internal function]: think\Error::appException(Object(think\exception\RouteNotFoundException))
#3 {main}
  thrown
[ error ] Uncaught exception 'think\exception\ErrorException' with message 'Argument 1 passed to app\lib\exception\ExceptionHandler::render() must be an instance of think\Exception, instance of think\exception\RouteNotFoundException given, called in C:\Users\cheyod\Desktop\Home\WWW\bigbase\thinkphp\library\think\Error.php on line 47 and defined' in C:\Users\cheyod\Desktop\Home\WWW\bigbase\application\lib\exception\ExceptionHandler.php:15
Stack trace:
#0 C:\Users\cheyod\Desktop\Home\WWW\bigbase\application\lib\exception\ExceptionHandler.php(15): think\Error::appError(4096, 'Argument 1 pass...', 'C:\\Users\\cheyod...', 15, Array)
#1 C:\Users\cheyod\Desktop\Home\WWW\bigbase\thinkphp\library\think\Error.php(47): app\lib\exception\ExceptionHandler->render(Object(think\exception\RouteNotFoundException))
#2 [internal function]: think\Error::appException(Object(think\exception\RouteNotFoundException))
#3 {main}
  thrown
---------------------------------------------------------------
[ 2017-08-27T14:21:38+08:00 ] 127.0.0.1 127.0.0.1 GET /index.php/v1/product
[ error ] [1]Uncaught exception 'think\exception\ErrorException' with message 'Argument 1 passed to app\lib\exception\ExceptionHandler::render() must be an instance of think\Exception, instance of think\exception\RouteNotFoundException given, called in C:\Users\cheyod\Desktop\Home\WWW\bigbase\thinkphp\library\think\Error.php on line 47 and defined' in C:\Users\cheyod\Desktop\Home\WWW\bigbase\application\lib\exception\ExceptionHandler.php:15
Stack trace:
#0 C:\Users\cheyod\Desktop\Home\WWW\bigbase\application\lib\exception\ExceptionHandler.php(15): think\Error::appError(4096, 'Argument 1 pass...', 'C:\\Users\\cheyod...', 15, Array)
#1 C:\Users\cheyod\Desktop\Home\WWW\bigbase\thinkphp\library\think\Error.php(47): app\lib\exception\ExceptionHandler->render(Object(think\exception\RouteNotFoundException))
#2 [internal function]: think\Error::appException(Object(think\exception\RouteNotFoundException))
#3 {main}
  thrown
[ error ] Uncaught exception 'think\exception\ErrorException' with message 'Argument 1 passed to app\lib\exception\ExceptionHandler::render() must be an instance of think\Exception, instance of think\exception\RouteNotFoundException given, called in C:\Users\cheyod\Desktop\Home\WWW\bigbase\thinkphp\library\think\Error.php on line 47 and defined' in C:\Users\cheyod\Desktop\Home\WWW\bigbase\application\lib\exception\ExceptionHandler.php:15
Stack trace:
#0 C:\Users\cheyod\Desktop\Home\WWW\bigbase\application\lib\exception\ExceptionHandler.php(15): think\Error::appError(4096, 'Argument 1 pass...', 'C:\\Users\\cheyod...', 15, Array)
#1 C:\Users\cheyod\Desktop\Home\WWW\bigbase\thinkphp\library\think\Error.php(47): app\lib\exception\ExceptionHandler->render(Object(think\exception\RouteNotFoundException))
#2 [internal function]: think\Error::appException(Object(think\exception\RouteNotFoundException))
#3 {main}
  thrown
